Workbook

Sheet AA7050
K1: 1
B2: FINDING PECLET NUMBER | C2: kg/m3 | D2: m | E2: J/kgK | F2: W/mK | K2: 1
B3: Cutting Speed, v | C3: Density, rho | D3: Half-width, b | E3: Specific Heat, c | F3: Thermal Conductivity, k | G3: Peclet Number, Pe | H3: Temperature, T | I3: Tool Width
B4: 4 | C4: 2700 | D4: =200*(10^-6) -> 0.0002 | E4: 896 | F4: 167 | G4: =(B4*C4*D4*E4)/(2*F4) -> 5.794491 | H4: 20 | I4: =5*10^-3 -> 0.005
B5: =B4*60 -> 240 | C5: m/min
B6: =B5*3.2 -> 768 | C6: sfm
B7: FINDING FLASH TEMPERATURE
B8: Cutting Force, F | C8: Density, rho | D8: Half-width, b | E8: Specific Heat, c | F8: Thermal Conductivity, k | G8: Peclet Number, Pe | H8: C4 | I8: Flash Temp (Pe>5) | J8: Flash Temp (Pe<5)
B9: =30*3 -> 90 | C9: =C4 -> 2700 | D9: =D4 -> 0.0002 | E9: =E4 -> 896 | F9: =F4 -> 167 | G9: =G4 -> 5.794491 | H9: =(0.00527*(G4^3))-(0.192*(G4^2))+2.39*G4 -> 8.4275304 | I9: =(0.399)*((2*B9*B4)/(F9*I4))*(SQRT((F9)/(C9*E9*B4*D9))) -> 101.06395 | J9: =(0.159*H9)*((2*B9)/(C9*E9*D9*I4)) -> 99.700694
H10: T vs Tcritical | I10: =(I9+20)/I61 -> 0.74730834 | L10: z [m] | M10: =M11*$D$4 -> 2e-06 | N10: =N11*$D$4 -> 4e-06 | O10: =O11*$D$4 -> 6e-06 | P10: =P11*$D$4 -> 8e-06 | Q10: =Q11*$D$4 -> 1e-05 | R10: =R11*$D$4 -> 1.2e-05 | S10: =S11*$D$4 -> 1.4e-05 | T10: =T11*$D$4 -> 1.6e-05 | ... BS10: =BS11*$D$4 -> 0.001
K11: z/b | L11: 0 | M11: 0.01 | N11: 0.02 | O11: 0.03 | P11: 0.04 | Q11: 0.05 | R11: 0.06 | S11: 0.07 | T11: 0.08 | U11: 0.09 | V11: 0.1 | W11: 0.11 | X11: 0.12 | Y11: 0.13 | Z11: 0.14 | AA11: 0.15 | AB11: 0.16 | AC11: 0.17 | AD11: 0.18 | AE11: 0.19 | AF11: 0.2 | AG11: 0.21 | AH11: 0.22 | AI11: 0.23 | AJ11: 0.24 | AK11: 0.25 | AL11: 0.26 | AM11: 0.27 | AN11: 0.28 | AO11: 0.29 | AP11: 0.3 | AQ11: 0.31 | AR11: 0.32 | AS11: 0.33 | AT11: 0.34 | AU11: 0.35 | AV11: 0.36 | AW11: 0.37 | AX11: 0.38 | AY11: 0.39 | AZ11: 0.4 | BA11: 0.41 | BB11: 0.42 | BC11: 0.43 | BD11: 0.44 | BE11: 0.45 | BF11: 0.46 | BG11: 0.47 | BH11: 0.48 | BI11: 0.49 | BJ11: 0.5 | BK11: 1 | BL11: 1.5 | BM11: 2 | BN11: 2.5 | BO11: 3 | BP11: 3.5 | BQ11: 4 | BR11: 4.5 | BS11: 5
B12: STEADY STATE TEMPERATURE
B13: x/b | D13: Peclet Number, Pe | E13: P+ | F13: P- | G13: Steady State Temp (x/b<-1) | H13: Steady State Temp (-1<x/b<1) | I13: Steady State Temp (1,x/b) | J13: summed temp profile | K13: normalized | L13: f(T)
B14: -2.001 | C14: =B14 -> -2.001 | D14: =G4 -> 5.794491 | E14: =($D$14*($B14+1))/2 -> -2.9001428 | F14: =($D$14*($B14-1))/2 -> -8.6946338 | G14: =((C14+1)*(EXP(E14))*(BESSELK(-E14,0)-BESSELK(-E14,1)))+((1-C14)*EXP(F14)*(BESSELK(-F14,0)-BESSELK(-F14,1))) -> 0.000345777 | J14: =G14+H14+I14 -> 0.000345777 | K14: =J14/MAX($J$14:$J$57) -> 0.0001765359 | L14: =IF($G$4>5,K14*$I$9,K14*$J$9)+20 -> 20.017841 | M14: =IF((1-ERF(M$10/SQRT(4*$F$4/($E$4*$C$4)*2*$D$4/$B$4)))*$L14<20,20,(1-ERF(M$10/SQRT(4*$F$4/($E$4*$C$4)*2*$D$4/$B$4)))*$L14) -> 20 | N14: =IF((1-ERF(N$10/SQRT(4*$F$4/($E$4*$C$4)*2*$D$4/$B$4)))*$L14<20,20,(1-ERF(N$10/SQRT(4*$F$4/($E$4*$C$4)*2*$D$4/$B$4)))*$L14) -> 20 | O14: =IF((1-ERF(O$10/SQRT(4*$F$4/($E$4*$C$4)*2*$D$4/$B$4)))*$L14<20,20,(1-ERF(O$10/SQRT(4*$F$4/($E$4*$C$4)*2*$D$4/$B$4)))*$L14) -> 20 | P14: =IF((1-ERF(P$10/SQRT(4*$F$4/($E$4*$C$4)*2*$D$4/$B$4)))*$L14<20,20,(1-ERF(P$10/SQRT(4*$F$4/($E$4*$C$4)*2*$D$4/$B$4)))*$L14) -> 20 | Q14: =IF((1-ERF(Q$10/SQRT(4*$F$4/($E$4*$C$4)*2*$D$4/$B$4)))*$L14<20,20,(1-ERF(Q$10/SQRT(4*$F$4/($E$4*$C$4)*2*$D$4/$B$4)))*$L14) -> 20 | R14: =IF((1-ERF(R$10/SQRT(4*$F$4/($E$4*$C$4)*2*$D$4/$B$4)))*$L14<20,20,(1-ERF(R$10/SQRT(4*$F$4/($E$4*$C$4)*2*$D$4/$B$4)))*$L14) -> 20 | S14: =IF((1-ERF(S$10/SQRT(4*$F$4/($E$4*$C$4)*2*$D$4/$B$4)))*$L14<20,20,(1-ERF(S$10/SQRT(4*$F$4/($E$4*$C$4)*2*$D$4/$B$4)))*$L14) -> 20 | T14: =IF((1-ERF(T$10/SQRT(4*$F$4/($E$4*$C$4)*2*$D$4/$B$4)))*$L14<20,20,(1-ERF(T$10/SQRT(4*$F$4/($E$4*$C$4)*2*$D$4/$B$4)))*$L14) -> 20 | ... BS14: =IF((1-ERF(BS$10/SQRT(4*$F$4/($E$4*$C$4)*2*$D$4/$B$4)))*$L14<20,20,(1-ERF(BS$10/SQRT(4*$F$4/($E$4*$C$4)*2*$D$4/$B$4)))*$L14) -> 20
B15: =B14+0.1 -> -1.901 | C15: =B15 -> -1.901 | E15: =($D$14*($B15+1))/2 -> -2.6104182 | F15: =($D$14*($B15-1))/2 -> -8.4049092 | G15: =((C15+1)*(EXP(E15))*(BESSELK(-E15,0)-BESSELK(-E15,1)))+((1-C15)*EXP(F15)*(BESSELK(-F15,0)-BESSELK(-F15,1))) -> 0.00064428553 | J15: =G15+H15+I15 -> 0.00064428553 | K15: =J15/MAX($J$14:$J$57) -> 0.00032893895 | L15: =IF($G$4>5,K15*$I$9,K15*$J$9)+20 -> 20.033244 | M15: =IF((1-ERF(M$10/SQRT(4*$F$4/($E$4*$C$4)*2*$D$4/$B$4)))*$L15<20,20,(1-ERF(M$10/SQRT(4*$F$4/($E$4*$C$4)*2*$D$4/$B$4)))*$L15) -> 20 | N15: =IF((1-ERF(N$10/SQRT(4*$F$4/($E$4*$C$4)*2*$D$4/$B$4)))*$L15<20,20,(1-ERF(N$10/SQRT(4*$F$4/($E$4*$C$4)*2*$D$4/$B$4)))*$L15) -> 20 | O15: =IF((1-ERF(O$10/SQRT(4*$F$4/($E$4*$C$4)*2*$D$4/$B$4)))*$L15<20,20,(1-ERF(O$10/SQRT(4*$F$4/($E$4*$C$4)*2*$D$4/$B$4)))*$L15) -> 20 | P15: =IF((1-ERF(P$10/SQRT(4*$F$4/($E$4*$C$4)*2*$D$4/$B$4)))*$L15<20,20,(1-ERF(P$10/SQRT(4*$F$4/($E$4*$C$4)*2*$D$4/$B$4)))*$L15) -> 20 | Q15: =IF((1-ERF(Q$10/SQRT(4*$F$4/($E$4*$C$4)*2*$D$4/$B$4)))*$L15<20,20,(1-ERF(Q$10/SQRT(4*$F$4/($E$4*$C$4)*2*$D$4/$B$4)))*$L15) -> 20 | R15: =IF((1-ERF(R$10/SQRT(4*$F$4/($E$4*$C$4)*2*$D$4/$B$4)))*$L15<20,20,(1-ERF(R$10/SQRT(4*$F$4/($E$4*$C$4)*2*$D$4/$B$4)))*$L15) -> 20 | S15: =IF((1-ERF(S$10/SQRT(4*$F$4/($E$4*$C$4)*2*$D$4/$B$4)))*$L15<20,20,(1-ERF(S$10/SQRT(4*$F$4/($E$4*$C$4)*2*$D$4/$B$4)))*$L15) -> 20 | T15: =IF((1-ERF(T$10/SQRT(4*$F$4/($E$4*$C$4)*2*$D$4/$B$4)))*$L15<20,20,(1-ERF(T$10/SQRT(4*$F$4/($E$4*$C$4)*2*$D$4/$B$4)))*$L15) -> 20 | ... BS15: =IF((1-ERF(BS$10/SQRT(4*$F$4/($E$4*$C$4)*2*$D$4/$B$4)))*$L15<20,20,(1-ERF(BS$10/SQRT(4*$F$4/($E$4*$C$4)*2*$D$4/$B$4)))*$L15) -> 20
B16: =B15+0.1 -> -1.801 | C16: =B16 -> -1.801 | E16: =($D$14*($B16+1))/2 -> -2.3206937 | F16: =($D$14*($B16-1))/2 -> -8.1151847 | G16: =((C16+1)*(EXP(E16))*(BESSELK(-E16,0)-BESSELK(-E16,1)))+((1-C16)*EXP(F16)*(BESSELK(-F16,0)-BESSELK(-F16,1))) -> 0.001205517 | J16: =G16+H16+I16 -> 0.001205517 | K16: =J16/MAX($J$14:$J$57) -> 0.00061547478 | L16: =IF($G$4>5,K16*$I$9,K16*$J$9)+20 -> 20.062202 | M16: =IF((1-ERF(M$10/SQRT(4*$F$4/($E$4*$C$4)*2*$D$4/$B$4)))*$L16<20,20,(1-ERF(M$10/SQRT(4*$F$4/($E$4*$C$4)*2*$D$4/$B$4)))*$L16) -> 20 | N16: =IF((1-ERF(N$10/SQRT(4*$F$4/($E$4*$C$4)*2*$D$4/$B$4)))*$L16<20,20,(1-ERF(N$10/SQRT(4*$F$4/($E$4*$C$4)*2*$D$4/$B$4)))*$L16) -> 20 | O16: =IF((1-ERF(O$10/SQRT(4*$F$4/($E$4*$C$4)*2*$D$4/$B$4)))*$L16<20,20,(1-ERF(O$10/SQRT(4*$F$4/($E$4*$C$4)*2*$D$4/$B$4)))*$L16) -> 20 | P16: =IF((1-ERF(P$10/SQRT(4*$F$4/($E$4*$C$4)*2*$D$4/$B$4)))*$L16<20,20,(1-ERF(P$10/SQRT(4*$F$4/($E$4*$C$4)*2*$D$4/$B$4)))*$L16) -> 20 | Q16: =IF((1-ERF(Q$10/SQRT(4*$F$4/($E$4*$C$4)*2*$D$4/$B$4)))*$L16<20,20,(1-ERF(Q$10/SQRT(4*$F$4/($E$4*$C$4)*2*$D$4/$B$4)))*$L16) -> 20 | R16: =IF((1-ERF(R$10/SQRT(4*$F$4/($E$4*$C$4)*2*$D$4/$B$4)))*$L16<20,20,(1-ERF(R$10/SQRT(4*$F$4/($E$4*$C$4)*2*$D$4/$B$4)))*$L16) -> 20 | S16: =IF((1-ERF(S$10/SQRT(4*$F$4/($E$4*$C$4)*2*$D$4/$B$4)))*$L16<20,20,(1-ERF(S$10/SQRT(4*$F$4/($E$4*$C$4)*2*$D$4/$B$4)))*$L16) -> 20 | T16: =IF((1-ERF(T$10/SQRT(4*$F$4/($E$4*$C$4)*2*$D$4/$B$4)))*$L16<20,20,(1-ERF(T$10/SQRT(4*$F$4/($E$4*$C$4)*2*$D$4/$B$4)))*$L16) -> 20 | ... BS16: =IF((1-ERF(BS$10/SQRT(4*$F$4/($E$4*$C$4)*2*$D$4/$B$4)))*$L16<20,20,(1-ERF(BS$10/SQRT(4*$F$4/($E$4*$C$4)*2*$D$4/$B$4)))*$L16) -> 20
B17: =B16+0.1 -> -1.701 | C17: =B17 -> -1.701 | E17: =($D$14*($B17+1))/2 -> -2.0309691 | F17: =($D$14*($B17-1))/2 -> -7.8254601 | G17: =((C17+1)*(EXP(E17))*(BESSELK(-E17,0)-BESSELK(-E17,1)))+((1-C17)*EXP(F17)*(BESSELK(-F17,0)-BESSELK(-F17,1))) -> 0.0022671749 | J17: =G17+H17+I17 -> 0.0022671749 | K17: =J17/MAX($J$14:$J$57) -> 0.0011575025 | L17: =IF($G$4>5,K17*$I$9,K17*$J$9)+20 -> 20.116982 | M17: =IF((1-ERF(M$10/SQRT(4*$F$4/($E$4*$C$4)*2*$D$4/$B$4)))*$L17<20,20,(1-ERF(M$10/SQRT(4*$F$4/($E$4*$C$4)*2*$D$4/$B$4)))*$L17) -> 20 | N17: =IF((1-ERF(N$10/SQRT(4*$F$4/($E$4*$C$4)*2*$D$4/$B$4)))*$L17<20,20,(1-ERF(N$10/SQRT(4*$F$4/($E$4*$C$4)*2*$D$4/$B$4)))*$L17) -> 20 | O17: =IF((1-ERF(O$10/SQRT(4*$F$4/($E$4*$C$4)*2*$D$4/$B$4)))*$L17<20,20,(1-ERF(O$10/SQRT(4*$F$4/($E$4*$C$4)*2*$D$4/$B$4)))*$L17) -> 20 | P17: =IF((1-ERF(P$10/SQRT(4*$F$4/($E$4*$C$4)*2*$D$4/$B$4)))*$L17<20,20,(1-ERF(P$10/SQRT(4*$F$4/($E$4*$C$4)*2*$D$4/$B$4)))*$L17) -> 20 | Q17: =IF((1-ERF(Q$10/SQRT(4*$F$4/($E$4*$C$4)*2*$D$4/$B$4)))*$L17<20,20,(1-ERF(Q$10/SQRT(4*$F$4/($E$4*$C$4)*2*$D$4/$B$4)))*$L17) -> 20 | R17: =IF((1-ERF(R$10/SQRT(4*$F$4/($E$4*$C$4)*2*$D$4/$B$4)))*$L17<20,20,(1-ERF(R$10/SQRT(4*$F$4/($E$4*$C$4)*2*$D$4/$B$4)))*$L17) -> 20 | S17: =IF((1-ERF(S$10/SQRT(4*$F$4/($E$4*$C$4)*2*$D$4/$B$4)))*$L17<20,20,(1-ERF(S$10/SQRT(4*$F$4/($E$4*$C$4)*2*$D$4/$B$4)))*$L17) -> 20 | T17: =IF((1-ERF(T$10/SQRT(4*$F$4/($E$4*$C$4)*2*$D$4/$B$4)))*$L17<20,20,(1-ERF(T$10/SQRT(4*$F$4/($E$4*$C$4)*2*$D$4/$B$4)))*$L17) -> 20 | ... BS17: =IF((1-ERF(BS$10/SQRT(4*$F$4/($E$4*$C$4)*2*$D$4/$B$4)))*$L17<20,20,(1-ERF(BS$10/SQRT(4*$F$4/($E$4*$C$4)*2*$D$4/$B$4)))*$L17) -> 20
B18: =B17+0.1 -> -1.601 | C18: =B18 -> -1.601 | E18: =($D$14*($B18+1))/2 -> -1.7412446 | F18: =($D$14*($B18-1))/2 -> -7.5357356 | G18: =((C18+1)*(EXP(E18))*(BESSELK(-E18,0)-BESSELK(-E18,1)))+((1-C18)*EXP(F18)*(BESSELK(-F18,0)-BESSELK(-F18,1))) -> 0.004291166 | J18: =G18+H18+I18 -> 0.004291166 | K18: =J18/MAX($J$14:$J$57) -> 0.0021908479 | L18: =IF($G$4>5,K18*$I$9,K18*$J$9)+20 -> 20.221416 | M18: =IF((1-ERF(M$10/SQRT(4*$F$4/($E$4*$C$4)*2*$D$4/$B$4)))*$L18<20,20,(1-ERF(M$10/SQRT(4*$F$4/($E$4*$C$4)*2*$D$4/$B$4)))*$L18) -> 20 | N18: =IF((1-ERF(N$10/SQRT(4*$F$4/($E$4*$C$4)*2*$D$4/$B$4)))*$L18<20,20,(1-ERF(N$10/SQRT(4*$F$4/($E$4*$C$4)*2*$D$4/$B$4)))*$L18) -> 20 | O18: =IF((1-ERF(O$10/SQRT(4*$F$4/($E$4*$C$4)*2*$D$4/$B$4)))*$L18<20,20,(1-ERF(O$10/SQRT(4*$F$4/($E$4*$C$4)*2*$D$4/$B$4)))*$L18) -> 20 | P18: =IF((1-ERF(P$10/SQRT(4*$F$4/($E$4*$C$4)*2*$D$4/$B$4)))*$L18<20,20,(1-ERF(P$10/SQRT(4*$F$4/($E$4*$C$4)*2*$D$4/$B$4)))*$L18) -> 20 | Q18: =IF((1-ERF(Q$10/SQRT(4*$F$4/($E$4*$C$4)*2*$D$4/$B$4)))*$L18<20,20,(1-ERF(Q$10/SQRT(4*$F$4/($E$4*$C$4)*2*$D$4/$B$4)))*$L18) -> 20 | R18: =IF((1-ERF(R$10/SQRT(4*$F$4/($E$4*$C$4)*2*$D$4/$B$4)))*$L18<20,20,(1-ERF(R$10/SQRT(4*$F$4/($E$4*$C$4)*2*$D$4/$B$4)))*$L18) -> 20 | S18: =IF((1-ERF(S$10/SQRT(4*$F$4/($E$4*$C$4)*2*$D$4/$B$4)))*$L18<20,20,(1-ERF(S$10/SQRT(4*$F$4/($E$4*$C$4)*2*$D$4/$B$4)))*$L18) -> 20 | T18: =IF((1-ERF(T$10/SQRT(4*$F$4/($E$4*$C$4)*2*$D$4/$B$4)))*$L18<20,20,(1-ERF(T$10/SQRT(4*$F$4/($E$4*$C$4)*2*$D$4/$B$4)))*$L18) -> 20 | ... BS18: =IF((1-ERF(BS$10/SQRT(4*$F$4/($E$4*$C$4)*2*$D$4/$B$4)))*$L18<20,20,(1-ERF(BS$10/SQRT(4*$F$4/($E$4*$C$4)*2*$D$4/$B$4)))*$L18) -> 20
B19: =B18+0.1 -> -1.501 | C19: =B19 -> -1.501 | E19: =($D$14*($B19+1))/2 -> -1.45152 | F19: =($D$14*($B19-1))/2 -> -7.246011 | G19: =((C19+1)*(EXP(E19))*(BESSELK(-E19,0)-BESSELK(-E19,1)))+((1-C19)*EXP(F19)*(BESSELK(-F19,0)-BESSELK(-F19,1))) -> 0.0081895943 | J19: =G19+H19+I19 -> 0.0081895943 | K19: =J19/MAX($J$14:$J$57) -> 0.0041811842 | L19: =IF($G$4>5,K19*$I$9,K19*$J$9)+20 -> 20.422567 | M19: =IF((1-ERF(M$10/SQRT(4*$F$4/($E$4*$C$4)*2*$D$4/$B$4)))*$L19<20,20,(1-ERF(M$10/SQRT(4*$F$4/($E$4*$C$4)*2*$D$4/$B$4)))*$L19) -> 20.145221 | N19: =IF((1-ERF(N$10/SQRT(4*$F$4/($E$4*$C$4)*2*$D$4/$B$4)))*$L19<20,20,(1-ERF(N$10/SQRT(4*$F$4/($E$4*$C$4)*2*$D$4/$B$4)))*$L19) -> 20 | O19: =IF((1-ERF(O$10/SQRT(4*$F$4/($E$4*$C$4)*2*$D$4/$B$4)))*$L19<20,20,(1-ERF(O$10/SQRT(4*$F$4/($E$4*$C$4)*2*$D$4/$B$4)))*$L19) -> 20 | P19: =IF((1-ERF(P$10/SQRT(4*$F$4/($E$4*$C$4)*2*$D$4/$B$4)))*$L19<20,20,(1-ERF(P$10/SQRT(4*$F$4/($E$4*$C$4)*2*$D$4/$B$4)))*$L19) -> 20 | Q19: =IF((1-ERF(Q$10/SQRT(4*$F$4/($E$4*$C$4)*2*$D$4/$B$4)))*$L19<20,20,(1-ERF(Q$10/SQRT(4*$F$4/($E$4*$C$4)*2*$D$4/$B$4)))*$L19) -> 20 | R19: =IF((1-ERF(R$10/SQRT(4*$F$4/($E$4*$C$4)*2*$D$4/$B$4)))*$L19<20,20,(1-ERF(R$10/SQRT(4*$F$4/($E$4*$C$4)*2*$D$4/$B$4)))*$L19) -> 20 | S19: =IF((1-ERF(S$10/SQRT(4*$F$4/($E$4*$C$4)*2*$D$4/$B$4)))*$L19<20,20,(1-ERF(S$10/SQRT(4*$F$4/($E$4*$C$4)*2*$D$4/$B$4)))*$L19) -> 20 | T19: =IF((1-ERF(T$10/SQRT(4*$F$4/($E$4*$C$4)*2*$D$4/$B$4)))*$L19<20,20,(1-ERF(T$10/SQRT(4*$F$4/($E$4*$C$4)*2*$D$4/$B$4)))*$L19) -> 20 | ... BS19: =IF((1-ERF(BS$10/SQRT(4*$F$4/($E$4*$C$4)*2*$D$4/$B$4)))*$L19<20,20,(1-ERF(BS$10/SQRT(4*$F$4/($E$4*$C$4)*2*$D$4/$B$4)))*$L19) -> 20
B20: =B19+0.1 -> -1.401 | C20: =B20 -> -1.401 | E20: =($D$14*($B20+1))/2 -> -1.1617954 | F20: =($D$14*($B20-1))/2 -> -6.9562865 | G20: =((C20+1)*(EXP(E20))*(BESSELK(-E20,0)-BESSELK(-E20,1)))+((1-C20)*EXP(F20)*(BESSELK(-F20,0)-BESSELK(-F20,1))) -> 0.015805505 | J20: =G20+H20+I20 -> 0.015805505 | K20: =J20/MAX($J$14:$J$57) -> 0.0080694755 | L20: =IF($G$4>5,K20*$I$9,K20*$J$9)+20 -> 20.815533 | M20: =IF((1-ERF(M$10/SQRT(4*$F$4/($E$4*$C$4)*2*$D$4/$B$4)))*$L20<20,20,(1-ERF(M$10/SQRT(4*$F$4/($E$4*$C$4)*2*$D$4/$B$4)))*$L20) -> 20.53285 | N20: =IF((1-ERF(N$10/SQRT(4*$F$4/($E$4*$C$4)*2*$D$4/$B$4)))*$L20<20,20,(1-ERF(N$10/SQRT(4*$F$4/($E$4*$C$4)*2*$D$4/$B$4)))*$L20) -> 20.250249 | O20: =IF((1-ERF(O$10/SQRT(4*$F$4/($E$4*$C$4)*2*$D$4/$B$4)))*$L20<20,20,(1-ERF(O$10/SQRT(4*$F$4/($E$4*$C$4)*2*$D$4/$B$4)))*$L20) -> 20 | P20: =IF((1-ERF(P$10/SQRT(4*$F$4/($E$4*$C$4)*2*$D$4/$B$4)))*$L20<20,20,(1-ERF(P$10/SQRT(4*$F$4/($E$4*$C$4)*2*$D$4/$B$4)))*$L20) -> 20 | Q20: =IF((1-ERF(Q$10/SQRT(4*$F$4/($E$4*$C$4)*2*$D$4/$B$4)))*$L20<20,20,(1-ERF(Q$10/SQRT(4*$F$4/($E$4*$C$4)*2*$D$4/$B$4)))*$L20) -> 20 | R20: =IF((1-ERF(R$10/SQRT(4*$F$4/($E$4*$C$4)*2*$D$4/$B$4)))*$L20<20,20,(1-ERF(R$10/SQRT(4*$F$4/($E$4*$C$4)*2*$D$4/$B$4)))*$L20) -> 20 | S20: =IF((1-ERF(S$10/SQRT(4*$F$4/($E$4*$C$4)*2*$D$4/$B$4)))*$L20<20,20,(1-ERF(S$10/SQRT(4*$F$4/($E$4*$C$4)*2*$D$4/$B$4)))*$L20) -> 20 | T20: =IF((1-ERF(T$10/SQRT(4*$F$4/($E$4*$C$4)*2*$D$4/$B$4)))*$L20<20,20,(1-ERF(T$10/SQRT(4*$F$4/($E$4*$C$4)*2*$D$4/$B$4)))*$L20) -> 20 | ... BS20: =IF((1-ERF(BS$10/SQRT(4*$F$4/($E$4*$C$4)*2*$D$4/$B$4)))*$L20<20,20,(1-ERF(BS$10/SQRT(4*$F$4/($E$4*$C$4)*2*$D$4/$B$4)))*$L20) -> 20
B21: =B20+0.1 -> -1.301 | C21: =B21 -> -1.301 | E21: =($D$14*($B21+1))/2 -> -0.8720709 | F21: =($D$14*($B21-1))/2 -> -6.6665619 | G21: =((C21+1)*(EXP(E21))*(BESSELK(-E21,0)-BESSELK(-E21,1)))+((1-C21)*EXP(F21)*(BESSELK(-F21,0)-BESSELK(-F21,1))) -> 0.030998437 | J21: =G21+H21+I21 -> 0.030998437 | K21: =J21/MAX($J$14:$J$57) -> 0.015826203 | L21: =IF($G$4>5,K21*$I$9,K21*$J$9)+20 -> 21.599459 | M21: =IF((1-ERF(M$10/SQRT(4*$F$4/($E$4*$C$4)*2*$D$4/$B$4)))*$L21<20,20,(1-ERF(M$10/SQRT(4*$F$4/($E$4*$C$4)*2*$D$4/$B$4)))*$L21) -> 21.30613 | N21: =IF((1-ERF(N$10/SQRT(4*$F$4/($E$4*$C$4)*2*$D$4/$B$4)))*$L21<20,20,(1-ERF(N$10/SQRT(4*$F$4/($E$4*$C$4)*2*$D$4/$B$4)))*$L21) -> 21.012886 | O21: =IF((1-ERF(O$10/SQRT(4*$F$4/($E$4*$C$4)*2*$D$4/$B$4)))*$L21<20,20,(1-ERF(O$10/SQRT(4*$F$4/($E$4*$C$4)*2*$D$4/$B$4)))*$L21) -> 20.719812 | P21: =IF((1-ERF(P$10/SQRT(4*$F$4/($E$4*$C$4)*2*$D$4/$B$4)))*$L21<20,20,(1-ERF(P$10/SQRT(4*$F$4/($E$4*$C$4)*2*$D$4/$B$4)))*$L21) -> 20.426993 | Q21: =IF((1-ERF(Q$10/SQRT(4*$F$4/($E$4*$C$4)*2*$D$4/$B$4)))*$L21<20,20,(1-ERF(Q$10/SQRT(4*$F$4/($E$4*$C$4)*2*$D$4/$B$4)))*$L21) -> 20.134513 | R21: =IF((1-ERF(R$10/SQRT(4*$F$4/($E$4*$C$4)*2*$D$4/$B$4)))*$L21<20,20,(1-ERF(R$10/SQRT(4*$F$4/($E$4*$C$4)*2*$D$4/$B$4)))*$L21) -> 20 | S21: =IF((1-ERF(S$10/SQRT(4*$F$4/($E$4*$C$4)*2*$D$4/$B$4)))*$L21<20,20,(1-ERF(S$10/SQRT(4*$F$4/($E$4*$C$4)*2*$D$4/$B$4)))*$L21) -> 20 | T21: =IF((1-ERF(T$10/SQRT(4*$F$4/($E$4*$C$4)*2*$D$4/$B$4)))*$L21<20,20,(1-ERF(T$10/SQRT(4*$F$4/($E$4*$C$4)*2*$D$4/$B$4)))*$L21) -> 20 | ... BS21: =IF((1-ERF(BS$10/SQRT(4*$F$4/($E$4*$C$4)*2*$D$4/$B$4)))*$L21<20,20,(1-ERF(BS$10/SQRT(4*$F$4/($E$4*$C$4)*2*$D$4/$B$4)))*$L21) -> 20
B22: =B21+0.1 -> -1.201 | C22: =B22 -> -1.201 | E22: =($D$14*($B22+1))/2 -> -0.58234635 | F22: =($D$14*($B22-1))/2 -> -6.3768374 | G22: =((C22+1)*(EXP(E22))*(BESSELK(-E22,0)-BESSELK(-E22,1)))+((1-C22)*EXP(F22)*(BESSELK(-F22,0)-BESSELK(-F22,1))) -> 0.062366897 | J22: =G22+H22+I22 -> 0.062366897 | K22: =J22/MAX($J$14:$J$57) -> 0.031841319 | L22: =IF($G$4>5,K22*$I$9,K22*$J$9)+20 -> 23.21801 | M22: =IF((1-ERF(M$10/SQRT(4*$F$4/($E$4*$C$4)*2*$D$4/$B$4)))*$L22<20,20,(1-ERF(M$10/SQRT(4*$F$4/($E$4*$C$4)*2*$D$4/$B$4)))*$L22) -> 22.9027 | N22: =IF((1-ERF(N$10/SQRT(4*$F$4/($E$4*$C$4)*2*$D$4/$B$4)))*$L22<20,20,(1-ERF(N$10/SQRT(4*$F$4/($E$4*$C$4)*2*$D$4/$B$4)))*$L22) -> 22.587482 | O22: =IF((1-ERF(O$10/SQRT(4*$F$4/($E$4*$C$4)*2*$D$4/$B$4)))*$L22<20,20,(1-ERF(O$10/SQRT(4*$F$4/($E$4*$C$4)*2*$D$4/$B$4)))*$L22) -> 22.272447 | P22: =IF((1-ERF(P$10/SQRT(4*$F$4/($E$4*$C$4)*2*$D$4/$B$4)))*$L22<20,20,(1-ERF(P$10/SQRT(4*$F$4/($E$4*$C$4)*2*$D$4/$B$4)))*$L22) -> 21.957685 | Q22: =IF((1-ERF(Q$10/SQRT(4*$F$4/($E$4*$C$4)*2*$D$4/$B$4)))*$L22<20,20,(1-ERF(Q$10/SQRT(4*$F$4/($E$4*$C$4)*2*$D$4/$B$4)))*$L22) -> 21.643288 | R22: =IF((1-ERF(R$10/SQRT(4*$F$4/($E$4*$C$4)*2*$D$4/$B$4)))*$L22<20,20,(1-ERF(R$10/SQRT(4*$F$4/($E$4*$C$4)*2*$D$4/$B$4)))*$L22) -> 21.329346 | S22: =IF((1-ERF(S$10/SQRT(4*$F$4/($E$4*$C$4)*2*$D$4/$B$4)))*$L22<20,20,(1-ERF(S$10/SQRT(4*$F$4/($E$4*$C$4)*2*$D$4/$B$4)))*$L22) -> 21.01595 | T22: =IF((1-ERF(T$10/SQRT(4*$F$4/($E$4*$C$4)*2*$D$4/$B$4)))*$L22<20,20,(1-ERF(T$10/SQRT(4*$F$4/($E$4*$C$4)*2*$D$4/$B$4)))*$L22) -> 20.703188 | ... BS22: =IF((1-ERF(BS$10/SQRT(4*$F$4/($E$4*$C$4)*2*$D$4/$B$4)))*$L22<20,20,(1-ERF(BS$10/SQRT(4*$F$4/($E$4*$C$4)*2*$D$4/$B$4)))*$L22) -> 20
B23: =B22+0.1 -> -1.101 | C23: =B23 -> -1.101 | E23: =($D$14*($B23+1))/2 -> -0.2926218 | F23: =($D$14*($B23-1))/2 -> -6.0871128 | G23: =((C23+1)*(EXP(E23))*(BESSELK(-E23,0)-BESSELK(-E23,1)))+((1-C23)*EXP(F23)*(BESSELK(-F23,0)-BESSELK(-F23,1))) -> 0.13176243 | J23: =G23+H23+I23 -> 0.13176243 | K23: =J23/MAX($J$14:$J$57) -> 0.067271097 | L23: =IF($G$4>5,K23*$I$9,K23*$J$9)+20 -> 26.798683 | M23: =IF((1-ERF(M$10/SQRT(4*$F$4/($E$4*$C$4)*2*$D$4/$B$4)))*$L23<20,20,(1-ERF(M$10/SQRT(4*$F$4/($E$4*$C$4)*2*$D$4/$B$4)))*$L23) -> 26.434747 | N23: =IF((1-ERF(N$10/SQRT(4*$F$4/($E$4*$C$4)*2*$D$4/$B$4)))*$L23<20,20,(1-ERF(N$10/SQRT(4*$F$4/($E$4*$C$4)*2*$D$4/$B$4)))*$L23) -> 26.070916 | O23: =IF((1-ERF(O$10/SQRT(4*$F$4/($E$4*$C$4)*2*$D$4/$B$4)))*$L23<20,20,(1-ERF(O$10/SQRT(4*$F$4/($E$4*$C$4)*2*$D$4/$B$4)))*$L23) -> 25.707296 | P23: =IF((1-ERF(P$10/SQRT(4*$F$4/($E$4*$C$4)*2*$D$4/$B$4)))*$L23<20,20,(1-ERF(P$10/SQRT(4*$F$4/($E$4*$C$4)*2*$D$4/$B$4)))*$L23) -> 25.343992 | Q23: =IF((1-ERF(Q$10/SQRT(4*$F$4/($E$4*$C$4)*2*$D$4/$B$4)))*$L23<20,20,(1-ERF(Q$10/SQRT(4*$F$4/($E$4*$C$4)*2*$D$4/$B$4)))*$L23) -> 24.981109 | R23: =IF((1-ERF(R$10/SQRT(4*$F$4/($E$4*$C$4)*2*$D$4/$B$4)))*$L23<20,20,(1-ERF(R$10/SQRT(4*$F$4/($E$4*$C$4)*2*$D$4/$B$4)))*$L23) -> 24.618751 | S23: =IF((1-ERF(S$10/SQRT(4*$F$4/($E$4*$C$4)*2*$D$4/$B$4)))*$L23<20,20,(1-ERF(S$10/SQRT(4*$F$4/($E$4*$C$4)*2*$D$4/$B$4)))*$L23) -> 24.257022 | T23: =IF((1-ERF(T$10/SQRT(4*$F$4/($E$4*$C$4)*2*$D$4/$B$4)))*$L23<20,20,(1-ERF(T$10/SQRT(4*$F$4/($E$4*$C$4)*2*$D$4/$B$4)))*$L23) -> 23.896026 | ... BS23: =IF((1-ERF(BS$10/SQRT(4*$F$4/($E$4*$C$4)*2*$D$4/$B$4)))*$L23<20,20,(1-ERF(BS$10/SQRT(4*$F$4/($E$4*$C$4)*2*$D$4/$B$4)))*$L23) -> 20
B24: =B23+0.1 -> -1.001 | C24: =B24 -> -1.001 | E24: =($D$14*($B24+1))/2 -> -0.0028972455 | F24: =($D$14*($B24-1))/2 -> -5.7973883 | G24: =((C24+1)*(EXP(E24))*(BESSELK(-E24,0)-BESSELK(-E24,1)))+((1-C24)*EXP(F24)*(BESSELK(-F24,0)-BESSELK(-F24,1))) -> 0.33820406 | J24: =G24+H24+I24 -> 0.33820406 | K24: =J24/MAX($J$14:$J$57) -> 0.17266954 | L24: =IF($G$4>5,K24*$I$9,K24*$J$9)+20 -> 37.450666 | M24: =IF((1-ERF(M$10/SQRT(4*$F$4/($E$4*$C$4)*2*$D$4/$B$4)))*$L24<20,20,(1-ERF(M$10/SQRT(4*$F$4/($E$4*$C$4)*2*$D$4/$B$4)))*$L24) -> 36.942072 | N24: =IF((1-ERF(N$10/SQRT(4*$F$4/($E$4*$C$4)*2*$D$4/$B$4)))*$L24<20,20,(1-ERF(N$10/SQRT(4*$F$4/($E$4*$C$4)*2*$D$4/$B$4)))*$L24) -> 36.433625 | O24: =IF((1-ERF(O$10/SQRT(4*$F$4/($E$4*$C$4)*2*$D$4/$B$4)))*$L24<20,20,(1-ERF(O$10/SQRT(4*$F$4/($E$4*$C$4)*2*$D$4/$B$4)))*$L24) -> 35.925473 | P24: =IF((1-ERF(P$10/SQRT(4*$F$4/($E$4*$C$4)*2*$D$4/$B$4)))*$L24<20,20,(1-ERF(P$10/SQRT(4*$F$4/($E$4*$C$4)*2*$D$4/$B$4)))*$L24) -> 35.417762 | Q24: =IF((1-ERF(Q$10/SQRT(4*$F$4/($E$4*$C$4)*2*$D$4/$B$4)))*$L24<20,20,(1-ERF(Q$10/SQRT(4*$F$4/($E$4*$C$4)*2*$D$4/$B$4)))*$L24) -> 34.91064 | R24: =IF((1-ERF(R$10/SQRT(4*$F$4/($E$4*$C$4)*2*$D$4/$B$4)))*$L24<20,20,(1-ERF(R$10/SQRT(4*$F$4/($E$4*$C$4)*2*$D$4/$B$4)))*$L24) -> 34.404251 | S24: =IF((1-ERF(S$10/SQRT(4*$F$4/($E$4*$C$4)*2*$D$4/$B$4)))*$L24<20,20,(1-ERF(S$10/SQRT(4*$F$4/($E$4*$C$4)*2*$D$4/$B$4)))*$L24) -> 33.898742 | T24: =IF((1-ERF(T$10/SQRT(4*$F$4/($E$4*$C$4)*2*$D$4/$B$4)))*$L24<20,20,(1-ERF(T$10/SQRT(4*$F$4/($E$4*$C$4)*2*$D$4/$B$4)))*$L24) -> 33.394257 | ... BS24: =IF((1-ERF(BS$10/SQRT(4*$F$4/($E$4*$C$4)*2*$D$4/$B$4)))*$L24<20,20,(1-ERF(BS$10/SQRT(4*$F$4/($E$4*$C$4)*2*$D$4/$B$4)))*$L24) -> 20
B25: =B24+0.1 -> -0.901 | C25: =B25 -> -0.901 | E25: =($D$14*($B25+1))/2 -> 0.28682731 | F25: =($D$14*($B25-1))/2 -> -5.5076637 | H25: =(((C25+1)*EXP(E25))*(BESSELK(E25,0)+BESSELK(E25,1)))+(((1-C25)*EXP(F25))*(BESSELK(-F25,0)-BESSELK(-F25,1))) -> 0.61048555 | J25: =G25+H25+I25 -> 0.61048555 | K25: =J25/MAX($J$14:$J$57) -> 0.31168242 | L25: =IF($G$4>5,K25*$I$9,K25*$J$9)+20 -> 51.499857 | M25: =IF((1-ERF(M$10/SQRT(4*$F$4/($E$4*$C$4)*2*$D$4/$B$4)))*$L25<20,20,(1-ERF(M$10/SQRT(4*$F$4/($E$4*$C$4)*2*$D$4/$B$4)))*$L25) -> 50.80047 | N25: =IF((1-ERF(N$10/SQRT(4*$F$4/($E$4*$C$4)*2*$D$4/$B$4)))*$L25<20,20,(1-ERF(N$10/SQRT(4*$F$4/($E$4*$C$4)*2*$D$4/$B$4)))*$L25) -> 50.101285 | O25: =IF((1-ERF(O$10/SQRT(4*$F$4/($E$4*$C$4)*2*$D$4/$B$4)))*$L25<20,20,(1-ERF(O$10/SQRT(4*$F$4/($E$4*$C$4)*2*$D$4/$B$4)))*$L25) -> 49.402505 | P25: =IF((1-ERF(P$10/SQRT(4*$F$4/($E$4*$C$4)*2*$D$4/$B$4)))*$L25<20,20,(1-ERF(P$10/SQRT(4*$F$4/($E$4*$C$4)*2*$D$4/$B$4)))*$L25) -> 48.704333 | Q25: =IF((1-ERF(Q$10/SQRT(4*$F$4/($E$4*$C$4)*2*$D$4/$B$4)))*$L25<20,20,(1-ERF(Q$10/SQRT(4*$F$4/($E$4*$C$4)*2*$D$4/$B$4)))*$L25) -> 48.006969 | R25: =IF((1-ERF(R$10/SQRT(4*$F$4/($E$4*$C$4)*2*$D$4/$B$4)))*$L25<20,20,(1-ERF(R$10/SQRT(4*$F$4/($E$4*$C$4)*2*$D$4/$B$4)))*$L25) -> 47.310614 | S25: =IF((1-ERF(S$10/SQRT(4*$F$4/($E$4*$C$4)*2*$D$4/$B$4)))*$L25<20,20,(1-ERF(S$10/SQRT(4*$F$4/($E$4*$C$4)*2*$D$4/$B$4)))*$L25) -> 46.615469 | T25: =IF((1-ERF(T$10/SQRT(4*$F$4/($E$4*$C$4)*2*$D$4/$B$4)))*$L25<20,20,(1-ERF(T$10/SQRT(4*$F$4/($E$4*$C$4)*2*$D$4/$B$4)))*$L25) -> 45.921732 | ... BS25: =IF((1-ERF(BS$10/SQRT(4*$F$4/($E$4*$C$4)*2*$D$4/$B$4)))*$L25<20,20,(1-ERF(BS$10/SQRT(4*$F$4/($E$4*$C$4)*2*$D$4/$B$4)))*$L25) -> 20
B26: =B25+0.1 -> -0.801 | C26: =B26 -> -0.801 | E26: =($D$14*($B26+1))/2 -> 0.57655186 | F26: =($D$14*($B26-1))/2 -> -5.2179392 | H26: =(((C26+1)*EXP(E26))*(BESSELK(E26,0)+BESSELK(E26,1)))+(((1-C26)*EXP(F26))*(BESSELK(-F26,0)-BESSELK(-F26,1))) -> 0.77345862 | J26: =G26+H26+I26 -> 0.77345862 | K26: =J26/MAX($J$14:$J$57) -> 0.39488806 | L26: =IF($G$4>5,K26*$I$9,K26*$J$9)+20 -> 59.908948 | M26: =IF((1-ERF(M$10/SQRT(4*$F$4/($E$4*$C$4)*2*$D$4/$B$4)))*$L26<20,20,(1-ERF(M$10/SQRT(4*$F$4/($E$4*$C$4)*2*$D$4/$B$4)))*$L26) -> 59.095362 | N26: =IF((1-ERF(N$10/SQRT(4*$F$4/($E$4*$C$4)*2*$D$4/$B$4)))*$L26<20,20,(1-ERF(N$10/SQRT(4*$F$4/($E$4*$C$4)*2*$D$4/$B$4)))*$L26) -> 58.282011 | O26: =IF((1-ERF(O$10/SQRT(4*$F$4/($E$4*$C$4)*2*$D$4/$B$4)))*$L26<20,20,(1-ERF(O$10/SQRT(4*$F$4/($E$4*$C$4)*2*$D$4/$B$4)))*$L26) -> 57.469132 | P26: =IF((1-ERF(P$10/SQRT(4*$F$4/($E$4*$C$4)*2*$D$4/$B$4)))*$L26<20,20,(1-ERF(P$10/SQRT(4*$F$4/($E$4*$C$4)*2*$D$4/$B$4)))*$L26) -> 56.656959 | Q26: =IF((1-ERF(Q$10/SQRT(4*$F$4/($E$4*$C$4)*2*$D$4/$B$4)))*$L26<20,20,(1-ERF(Q$10/SQRT(4*$F$4/($E$4*$C$4)*2*$D$4/$B$4)))*$L26) -> 55.845727 | R26: =IF((1-ERF(R$10/SQRT(4*$F$4/($E$4*$C$4)*2*$D$4/$B$4)))*$L26<20,20,(1-ERF(R$10/SQRT(4*$F$4/($E$4*$C$4)*2*$D$4/$B$4)))*$L26) -> 55.035669 | S26: =IF((1-ERF(S$10/SQRT(4*$F$4/($E$4*$C$4)*2*$D$4/$B$4)))*$L26<20,20,(1-ERF(S$10/SQRT(4*$F$4/($E$4*$C$4)*2*$D$4/$B$4)))*$L26) -> 54.227018 | T26: =IF((1-ERF(T$10/SQRT(4*$F$4/($E$4*$C$4)*2*$D$4/$B$4)))*$L26<20,20,(1-ERF(T$10/SQRT(4*$F$4/($E$4*$C$4)*2*$D$4/$B$4)))*$L26) -> 53.420005 | ... BS26: =IF((1-ERF(BS$10/SQRT(4*$F$4/($E$4*$C$4)*2*$D$4/$B$4)))*$L26<20,20,(1-ERF(BS$10/SQRT(4*$F$4/($E$4*$C$4)*2*$D$4/$B$4)))*$L26) -> 20
B27: =B26+0.1 -> -0.701 | C27: =B27 -> -0.701 | E27: =($D$14*($B27+1))/2 -> 0.86627641 | F27: =($D$14*($B27-1))/2 -> -4.9282146 | H27: =(((C27+1)*EXP(E27))*(BESSELK(E27,0)+BESSELK(E27,1)))+(((1-C27)*EXP(F27))*(BESSELK(-F27,0)-BESSELK(-F27,1))) -> 0.90530232 | J27: =G27+H27+I27 -> 0.90530232 | K27: =J27/MAX($J$14:$J$57) -> 0.46220065 | L27: =IF($G$4>5,K27*$I$9,K27*$J$9)+20 -> 66.711824 | M27: =IF((1-ERF(M$10/SQRT(4*$F$4/($E$4*$C$4)*2*$D$4/$B$4)))*$L27<20,20,(1-ERF(M$10/SQRT(4*$F$4/($E$4*$C$4)*2*$D$4/$B$4)))*$L27) -> 65.805852 | N27: =IF((1-ERF(N$10/SQRT(4*$F$4/($E$4*$C$4)*2*$D$4/$B$4)))*$L27<20,20,(1-ERF(N$10/SQRT(4*$F$4/($E$4*$C$4)*2*$D$4/$B$4)))*$L27) -> 64.900143 | O27: =IF((1-ERF(O$10/SQRT(4*$F$4/($E$4*$C$4)*2*$D$4/$B$4)))*$L27<20,20,(1-ERF(O$10/SQRT(4*$F$4/($E$4*$C$4)*2*$D$4/$B$4)))*$L27) -> 63.994959 | P27: =IF((1-ERF(P$10/SQRT(4*$F$4/($E$4*$C$4)*2*$D$4/$B$4)))*$L27<20,20,(1-ERF(P$10/SQRT(4*$F$4/($E$4*$C$4)*2*$D$4/$B$4)))*$L27) -> 63.090561 | Q27: =IF((1-ERF(Q$10/SQRT(4*$F$4/($E$4*$C$4)*2*$D$4/$B$4)))*$L27<20,20,(1-ERF(Q$10/SQRT(4*$F$4/($E$4*$C$4)*2*$D$4/$B$4)))*$L27) -> 62.18721 | R27: =IF((1-ERF(R$10/SQRT(4*$F$4/($E$4*$C$4)*2*$D$4/$B$4)))*$L27<20,20,(1-ERF(R$10/SQRT(4*$F$4/($E$4*$C$4)*2*$D$4/$B$4)))*$L27) -> 61.285167 | S27: =IF((1-ERF(S$10/SQRT(4*$F$4/($E$4*$C$4)*2*$D$4/$B$4)))*$L27<20,20,(1-ERF(S$10/SQRT(4*$F$4/($E$4*$C$4)*2*$D$4/$B$4)))*$L27) -> 60.384691 | T27: =IF((1-ERF(T$10/SQRT(4*$F$4/($E$4*$C$4)*2*$D$4/$B$4)))*$L27<20,20,(1-ERF(T$10/SQRT(4*$F$4/($E$4*$C$4)*2*$D$4/$B$4)))*$L27) -> 59.486039 | ... BS27: =IF((1-ERF(BS$10/SQRT(4*$F$4/($E$4*$C$4)*2*$D$4/$B$4)))*$L27<20,20,(1-ERF(BS$10/SQRT(4*$F$4/($E$4*$C$4)*2*$D$4/$B$4)))*$L27) -> 20
B28: =B27+0.1 -> -0.601 | C28: =B28 -> -0.601 | E28: =($D$14*($B28+1))/2 -> 1.156001 | F28: =($D$14*($B28-1))/2 -> -4.6384901 | H28: =(((C28+1)*EXP(E28))*(BESSELK(E28,0)+BESSELK(E28,1)))+(((1-C28)*EXP(F28))*(BESSELK(-F28,0)-BESSELK(-F28,1))) -> 1.0194253 | J28: =G28+H28+I28 -> 1.0194253 | K28: =J28/MAX($J$14:$J$57) -> 0.52046598 | L28: =IF($G$4>5,K28*$I$9,K28*$J$9)+20 -> 72.600348 | M28: =IF((1-ERF(M$10/SQRT(4*$F$4/($E$4*$C$4)*2*$D$4/$B$4)))*$L28<20,20,(1-ERF(M$10/SQRT(4*$F$4/($E$4*$C$4)*2*$D$4/$B$4)))*$L28) -> 71.614408 | N28: =IF((1-ERF(N$10/SQRT(4*$F$4/($E$4*$C$4)*2*$D$4/$B$4)))*$L28<20,20,(1-ERF(N$10/SQRT(4*$F$4/($E$4*$C$4)*2*$D$4/$B$4)))*$L28) -> 70.628754 | O28: =IF((1-ERF(O$10/SQRT(4*$F$4/($E$4*$C$4)*2*$D$4/$B$4)))*$L28<20,20,(1-ERF(O$10/SQRT(4*$F$4/($E$4*$C$4)*2*$D$4/$B$4)))*$L28) -> 69.64367 | P28: =IF((1-ERF(P$10/SQRT(4*$F$4/($E$4*$C$4)*2*$D$4/$B$4)))*$L28<20,20,(1-ERF(P$10/SQRT(4*$F$4/($E$4*$C$4)*2*$D$4/$B$4)))*$L28) -> 68.659443 | Q28: =IF((1-ERF(Q$10/SQRT(4*$F$4/($E$4*$C$4)*2*$D$4/$B$4)))*$L28<20,20,(1-ERF(Q$10/SQRT(4*$F$4/($E$4*$C$4)*2*$D$4/$B$4)))*$L28) -> 67.676355 | R28: =IF((1-ERF(R$10/SQRT(4*$F$4/($E$4*$C$4)*2*$D$4/$B$4)))*$L28<20,20,(1-ERF(R$10/SQRT(4*$F$4/($E$4*$C$4)*2*$D$4/$B$4)))*$L28) -> 66.694691 | S28: =IF((1-ERF(S$10/SQRT(4*$F$4/($E$4*$C$4)*2*$D$4/$B$4)))*$L28<20,20,(1-ERF(S$10/SQRT(4*$F$4/($E$4*$C$4)*2*$D$4/$B$4)))*$L28) -> 65.714731 | T28: =IF((1-ERF(T$10/SQRT(4*$F$4/($E$4*$C$4)*2*$D$4/$B$4)))*$L28<20,20,(1-ERF(T$10/SQRT(4*$F$4/($E$4*$C$4)*2*$D$4/$B$4)))*$L28) -> 64.736757 | ... BS28: =IF((1-ERF(BS$10/SQRT(4*$F$4/($E$4*$C$4)*2*$D$4/$B$4)))*$L28<20,20,(1-ERF(BS$10/SQRT(4*$F$4/($E$4*$C$4)*2*$D$4/$B$4)))*$L28) -> 20
B29: =B28+0.1 -> -0.501 | C29: =B29 -> -0.501 | E29: =($D$14*($B29+1))/2 -> 1.4457255 | F29: =($D$14*($B29-1))/2 -> -4.3487655 | H29: =(((C29+1)*EXP(E29))*(BESSELK(E29,0)+BESSELK(E29,1)))+(((1-C29)*EXP(F29))*(BESSELK(-F29,0)-BESSELK(-F29,1))) -> 1.1216116 | J29: =G29+H29+I29 -> 1.1216116 | K29: =J29/MAX($J$14:$J$57) -> 0.57263702 | L29: =IF($G$4>5,K29*$I$9,K29*$J$9)+20 -> 77.87296 | M29: =IF((1-ERF(M$10/SQRT(4*$F$4/($E$4*$C$4)*2*$D$4/$B$4)))*$L29<20,20,(1-ERF(M$10/SQRT(4*$F$4/($E$4*$C$4)*2*$D$4/$B$4)))*$L29) -> 76.815416 | N29: =IF((1-ERF(N$10/SQRT(4*$F$4/($E$4*$C$4)*2*$D$4/$B$4)))*$L29<20,20,(1-ERF(N$10/SQRT(4*$F$4/($E$4*$C$4)*2*$D$4/$B$4)))*$L29) -> 75.758179 | O29: =IF((1-ERF(O$10/SQRT(4*$F$4/($E$4*$C$4)*2*$D$4/$B$4)))*$L29<20,20,(1-ERF(O$10/SQRT(4*$F$4/($E$4*$C$4)*2*$D$4/$B$4)))*$L29) -> 74.701553 | P29: =IF((1-ERF(P$10/SQRT(4*$F$4/($E$4*$C$4)*2*$D$4/$B$4)))*$L29<20,20,(1-ERF(P$10/SQRT(4*$F$4/($E$4*$C$4)*2*$D$4/$B$4)))*$L29) -> 73.645846 | Q29: =IF((1-ERF(Q$10/SQRT(4*$F$4/($E$4*$C$4)*2*$D$4/$B$4)))*$L29<20,20,(1-ERF(Q$10/SQRT(4*$F$4/($E$4*$C$4)*2*$D$4/$B$4)))*$L29) -> 72.591362 | R29: =IF((1-ERF(R$10/SQRT(4*$F$4/($E$4*$C$4)*2*$D$4/$B$4)))*$L29<20,20,(1-ERF(R$10/SQRT(4*$F$4/($E$4*$C$4)*2*$D$4/$B$4)))*$L29) -> 71.538404 | S29: =IF((1-ERF(S$10/SQRT(4*$F$4/($E$4*$C$4)*2*$D$4/$B$4)))*$L29<20,20,(1-ERF(S$10/SQRT(4*$F$4/($E$4*$C$4)*2*$D$4/$B$4)))*$L29) -> 70.487274 | T29: =IF((1-ERF(T$10/SQRT(4*$F$4/($E$4*$C$4)*2*$D$4/$B$4)))*$L29<20,20,(1-ERF(T$10/SQRT(4*$F$4/($E$4*$C$4)*2*$D$4/$B$4)))*$L29) -> 69.438274 | ... BS29: =IF((1-ERF(BS$10/SQRT(4*$F$4/($E$4*$C$4)*2*$D$4/$B$4)))*$L29<20,20,(1-ERF(BS$10/SQRT(4*$F$4/($E$4*$C$4)*2*$D$4/$B$4)))*$L29) -> 20
B30: =B29+0.1 -> -0.401 | C30: =B30 -> -0.401 | E30: =($D$14*($B30+1))/2 -> 1.7354501 | F30: =($D$14*($B30-1))/2 -> -4.059041 | H30: =(((C30+1)*EXP(E30))*(BESSELK(E30,0)+BESSELK(E30,1)))+(((1-C30)*EXP(F30))*(BESSELK(-F30,0)-BESSELK(-F30,1))) -> 1.2150187 | J30: =G30+H30+I30 -> 1.2150187 | K30: =J30/MAX($J$14:$J$57) -> 0.62032584 | L30: =IF($G$4>5,K30*$I$9,K30*$J$9)+20 -> 82.69258 | M30: =IF((1-ERF(M$10/SQRT(4*$F$4/($E$4*$C$4)*2*$D$4/$B$4)))*$L30<20,20,(1-ERF(M$10/SQRT(4*$F$4/($E$4*$C$4)*2*$D$4/$B$4)))*$L30) -> 81.569584 | N30: =IF((1-ERF(N$10/SQRT(4*$F$4/($E$4*$C$4)*2*$D$4/$B$4)))*$L30<20,20,(1-ERF(N$10/SQRT(4*$F$4/($E$4*$C$4)*2*$D$4/$B$4)))*$L30) -> 80.446913 | O30: =IF((1-ERF(O$10/SQRT(4*$F$4/($E$4*$C$4)*2*$D$4/$B$4)))*$L30<20,20,(1-ERF(O$10/SQRT(4*$F$4/($E$4*$C$4)*2*$D$4/$B$4)))*$L30) -> 79.324893 | P30: =IF((1-ERF(P$10/SQRT(4*$F$4/($E$4*$C$4)*2*$D$4/$B$4)))*$L30<20,20,(1-ERF(P$10/SQRT(4*$F$4/($E$4*$C$4)*2*$D$4/$B$4)))*$L30) -> 78.203847 | Q30: =IF((1-ERF(Q$10/SQRT(4*$F$4/($E$4*$C$4)*2*$D$4/$B$4)))*$L30<20,20,(1-ERF(Q$10/SQRT(4*$F$4/($E$4*$C$4)*2*$D$4/$B$4)))*$L30) -> 77.0841 | R30: =IF((1-ERF(R$10/SQRT(4*$F$4/($E$4*$C$4)*2*$D$4/$B$4)))*$L30<20,20,(1-ERF(R$10/SQRT(4*$F$4/($E$4*$C$4)*2*$D$4/$B$4)))*$L30) -> 75.965973 | S30: =IF((1-ERF(S$10/SQRT(4*$F$4/($E$4*$C$4)*2*$D$4/$B$4)))*$L30<20,20,(1-ERF(S$10/SQRT(4*$F$4/($E$4*$C$4)*2*$D$4/$B$4)))*$L30) -> 74.849789 | T30: =IF((1-ERF(T$10/SQRT(4*$F$4/($E$4*$C$4)*2*$D$4/$B$4)))*$L30<20,20,(1-ERF(T$10/SQRT(4*$F$4/($E$4*$C$4)*2*$D$4/$B$4)))*$L30) -> 73.735865 | ... BS30: =IF((1-ERF(BS$10/SQRT(4*$F$4/($E$4*$C$4)*2*$D$4/$B$4)))*$L30<20,20,(1-ERF(BS$10/SQRT(4*$F$4/($E$4*$C$4)*2*$D$4/$B$4)))*$L30) -> 20
B31: =B30+0.1 -> -0.301 | C31: =B31 -> -0.301 | E31: =($D$14*($B31+1))/2 -> 2.0251746 | F31: =($D$14*($B31-1))/2 -> -3.7693164 | H31: =(((C31+1)*EXP(E31))*(BESSELK(E31,0)+BESSELK(E31,1)))+(((1-C31)*EXP(F31))*(BESSELK(-F31,0)-BESSELK(-F31,1))) -> 1.3016011 | J31: =G31+H31+I31 -> 1.3016011 | K31: =J31/MAX($J$14:$J$57) -> 0.66453037 | L31: =IF($G$4>5,K31*$I$9,K31*$J$9)+20 -> 87.160065 | M31: =IF((1-ERF(M$10/SQRT(4*$F$4/($E$4*$C$4)*2*$D$4/$B$4)))*$L31<20,20,(1-ERF(M$10/SQRT(4*$F$4/($E$4*$C$4)*2*$D$4/$B$4)))*$L31) -> 85.976399 | N31: =IF((1-ERF(N$10/SQRT(4*$F$4/($E$4*$C$4)*2*$D$4/$B$4)))*$L31<20,20,(1-ERF(N$10/SQRT(4*$F$4/($E$4*$C$4)*2*$D$4/$B$4)))*$L31) -> 84.793075 | O31: =IF((1-ERF(O$10/SQRT(4*$F$4/($E$4*$C$4)*2*$D$4/$B$4)))*$L31<20,20,(1-ERF(O$10/SQRT(4*$F$4/($E$4*$C$4)*2*$D$4/$B$4)))*$L31) -> 83.610437 | P31: =IF((1-ERF(P$10/SQRT(4*$F$4/($E$4*$C$4)*2*$D$4/$B$4)))*$L31<20,20,(1-ERF(P$10/SQRT(4*$F$4/($E$4*$C$4)*2*$D$4/$B$4)))*$L31) -> 82.428827 | Q31: =IF((1-ERF(Q$10/SQRT(4*$F$4/($E$4*$C$4)*2*$D$4/$B$4)))*$L31<20,20,(1-ERF(Q$10/SQRT(4*$F$4/($E$4*$C$4)*2*$D$4/$B$4)))*$L31) -> 81.248585 | R31: =IF((1-ERF(R$10/SQRT(4*$F$4/($E$4*$C$4)*2*$D$4/$B$4)))*$L31<20,20,(1-ERF(R$10/SQRT(4*$F$4/($E$4*$C$4)*2*$D$4/$B$4)))*$L31) -> 80.070051 | S31: =IF((1-ERF(S$10/SQRT(4*$F$4/($E$4*$C$4)*2*$D$4/$B$4)))*$L31<20,20,(1-ERF(S$10/SQRT(4*$F$4/($E$4*$C$4)*2*$D$4/$B$4)))*$L31) -> 78.893564 | T31: =IF((1-ERF(T$10/SQRT(4*$F$4/($E$4*$C$4)*2*$D$4/$B$4)))*$L31<20,20,(1-ERF(T$10/SQRT(4*$F$4/($E$4*$C$4)*2*$D$4/$B$4)))*$L31) -> 77.719461 | ... BS31: =IF((1-ERF(BS$10/SQRT(4*$F$4/($E$4*$C$4)*2*$D$4/$B$4)))*$L31<20,20,(1-ERF(BS$10/SQRT(4*$F$4/($E$4*$C$4)*2*$D$4/$B$4)))*$L31) -> 20
B32: =B31+0.1 -> -0.201 | C32: =B32 -> -0.201 | E32: =($D$14*($B32+1))/2 -> 2.3148992 | F32: =($D$14*($B32-1))/2 -> -3.4795919 | H32: =(((C32+1)*EXP(E32))*(BESSELK(E32,0)+BESSELK(E32,1)))+(((1-C32)*EXP(F32))*(BESSELK(-F32,0)-BESSELK(-F32,1))) -> 1.3826675 | J32: =G32+H32+I32 -> 1.3826675 | K32: =J32/MAX($J$14:$J$57) -> 0.70591866 | L32: =IF($G$4>5,K32*$I$9,K32*$J$9)+20 -> 91.342929 | M32: =IF((1-ERF(M$10/SQRT(4*$F$4/($E$4*$C$4)*2*$D$4/$B$4)))*$L32<20,20,(1-ERF(M$10/SQRT(4*$F$4/($E$4*$C$4)*2*$D$4/$B$4)))*$L32) -> 90.102457 | N32: =IF((1-ERF(N$10/SQRT(4*$F$4/($E$4*$C$4)*2*$D$4/$B$4)))*$L32<20,20,(1-ERF(N$10/SQRT(4*$F$4/($E$4*$C$4)*2*$D$4/$B$4)))*$L32) -> 88.862346 | O32: =IF((1-ERF(O$10/SQRT(4*$F$4/($E$4*$C$4)*2*$D$4/$B$4)))*$L32<20,20,(1-ERF(O$10/SQRT(4*$F$4/($E$4*$C$4)*2*$D$4/$B$4)))*$L32) -> 87.622952 | P32: =IF((1-ERF(P$10/SQRT(4*$F$4/($E$4*$C$4)*2*$D$4/$B$4)))*$L32<20,20,(1-ERF(P$10/SQRT(4*$F$4/($E$4*$C$4)*2*$D$4/$B$4)))*$L32) -> 86.384635 | Q32: =IF((1-ERF(Q$10/SQRT(4*$F$4/($E$4*$C$4)*2*$D$4/$B$4)))*$L32<20,20,(1-ERF(Q$10/SQRT(4*$F$4/($E$4*$C$4)*2*$D$4/$B$4)))*$L32) -> 85.147753 | R32: =IF((1-ERF(R$10/SQRT(4*$F$4/($E$4*$C$4)*2*$D$4/$B$4)))*$L32<20,20,(1-ERF(R$10/SQRT(4*$F$4/($E$4*$C$4)*2*$D$4/$B$4)))*$L32) -> 83.912661 | S32: =IF((1-ERF(S$10/SQRT(4*$F$4/($E$4*$C$4)*2*$D$4/$B$4)))*$L32<20,20,(1-ERF(S$10/SQRT(4*$F$4/($E$4*$C$4)*2*$D$4/$B$4)))*$L32) -> 82.679714 | T32: =IF((1-ERF(T$10/SQRT(4*$F$4/($E$4*$C$4)*2*$D$4/$B$4)))*$L32<20,20,(1-ERF(T$10/SQRT(4*$F$4/($E$4*$C$4)*2*$D$4/$B$4)))*$L32) -> 81.449265 | ... BS32: =IF((1-ERF(BS$10/SQRT(4*$F$4/($E$4*$C$4)*2*$D$4/$B$4)))*$L32<20,20,(1-ERF(BS$10/SQRT(4*$F$4/($E$4*$C$4)*2*$D$4/$B$4)))*$L32) -> 20
B33: =B32+0.1 -> -0.101 | C33: =B33 -> -0.101 | E33: =($D$14*($B33+1))/2 -> 2.6046237 | F33: =($D$14*($B33-1))/2 -> -3.1898673 | H33: =(((C33+1)*EXP(E33))*(BESSELK(E33,0)+BESSELK(E33,1)))+(((1-C33)*EXP(F33))*(BESSELK(-F33,0)-BESSELK(-F33,1))) -> 1.4591377 | J33: =G33+H33+I33 -> 1.4591377 | K33: =J33/MAX($J$14:$J$57) -> 0.74496041 | L33: =IF($G$4>5,K33*$I$9,K33*$J$9)+20 -> 95.288642 | M33: =IF((1-ERF(M$10/SQRT(4*$F$4/($E$4*$C$4)*2*$D$4/$B$4)))*$L33<20,20,(1-ERF(M$10/SQRT(4*$F$4/($E$4*$C$4)*2*$D$4/$B$4)))*$L33) -> 93.994587 | N33: =IF((1-ERF(N$10/SQRT(4*$F$4/($E$4*$C$4)*2*$D$4/$B$4)))*$L33<20,20,(1-ERF(N$10/SQRT(4*$F$4/($E$4*$C$4)*2*$D$4/$B$4)))*$L33) -> 92.700906 | O33: =IF((1-ERF(O$10/SQRT(4*$F$4/($E$4*$C$4)*2*$D$4/$B$4)))*$L33<20,20,(1-ERF(O$10/SQRT(4*$F$4/($E$4*$C$4)*2*$D$4/$B$4)))*$L33) -> 91.407975 | P33: =IF((1-ERF(P$10/SQRT(4*$F$4/($E$4*$C$4)*2*$D$4/$B$4)))*$L33<20,20,(1-ERF(P$10/SQRT(4*$F$4/($E$4*$C$4)*2*$D$4/$B$4)))*$L33) -> 90.116167 | Q33: =IF((1-ERF(Q$10/SQRT(4*$F$4/($E$4*$C$4)*2*$D$4/$B$4)))*$L33<20,20,(1-ERF(Q$10/SQRT(4*$F$4/($E$4*$C$4)*2*$D$4/$B$4)))*$L33) -> 88.825855 | R33: =IF((1-ERF(R$10/SQRT(4*$F$4/($E$4*$C$4)*2*$D$4/$B$4)))*$L33<20,20,(1-ERF(R$10/SQRT(4*$F$4/($E$4*$C$4)*2*$D$4/$B$4)))*$L33) -> 87.537411 | S33: =IF((1-ERF(S$10/SQRT(4*$F$4/($E$4*$C$4)*2*$D$4/$B$4)))*$L33<20,20,(1-ERF(S$10/SQRT(4*$F$4/($E$4*$C$4)*2*$D$4/$B$4)))*$L33) -> 86.251205 | T33: =IF((1-ERF(T$10/SQRT(4*$F$4/($E$4*$C$4)*2*$D$4/$B$4)))*$L33<20,20,(1-ERF(T$10/SQRT(4*$F$4/($E$4*$C$4)*2*$D$4/$B$4)))*$L33) -> 84.967605 | ... BS33: =IF((1-ERF(BS$10/SQRT(4*$F$4/($E$4*$C$4)*2*$D$4/$B$4)))*$L33<20,20,(1-ERF(BS$10/SQRT(4*$F$4/($E$4*$C$4)*2*$D$4/$B$4)))*$L33) -> 20
B34: =B33+0.1 -> -0.001 | C34: =B34 -> -0.001 | E34: =($D$14*($B34+1))/2 -> 2.8943483 | F34: =($D$14*($B34-1))/2 -> -2.9001428 | H34: =(((C34+1)*EXP(E34))*(BESSELK(E34,0)+BESSELK(E34,1)))+(((1-C34)*EXP(F34))*(BESSELK(-F34,0)-BESSELK(-F34,1))) -> 1.5316742 | J34: =G34+H34+I34 -> 1.5316742 | K34: =J34/MAX($J$14:$J$57) -> 0.78199381 | L34: =IF($G$4>5,K34*$I$9,K34*$J$9)+20 -> 99.031384 | M34: =IF((1-ERF(M$10/SQRT(4*$F$4/($E$4*$C$4)*2*$D$4/$B$4)))*$L34<20,20,(1-ERF(M$10/SQRT(4*$F$4/($E$4*$C$4)*2*$D$4/$B$4)))*$L34) -> 97.686501 | N34: =IF((1-ERF(N$10/SQRT(4*$F$4/($E$4*$C$4)*2*$D$4/$B$4)))*$L34<20,20,(1-ERF(N$10/SQRT(4*$F$4/($E$4*$C$4)*2*$D$4/$B$4)))*$L34) -> 96.342007 | O34: =IF((1-ERF(O$10/SQRT(4*$F$4/($E$4*$C$4)*2*$D$4/$B$4)))*$L34<20,20,(1-ERF(O$10/SQRT(4*$F$4/($E$4*$C$4)*2*$D$4/$B$4)))*$L34) -> 94.998292 | P34: =IF((1-ERF(P$10/SQRT(4*$F$4/($E$4*$C$4)*2*$D$4/$B$4)))*$L34<20,20,(1-ERF(P$10/SQRT(4*$F$4/($E$4*$C$4)*2*$D$4/$B$4)))*$L34) -> 93.655745 | Q34: =IF((1-ERF(Q$10/SQRT(4*$F$4/($E$4*$C$4)*2*$D$4/$B$4)))*$L34<20,20,(1-ERF(Q$10/SQRT(4*$F$4/($E$4*$C$4)*2*$D$4/$B$4)))*$L34) -> 92.314752 | R34: =IF((1-ERF(R$10/SQRT(4*$F$4/($E$4*$C$4)*2*$D$4/$B$4)))*$L34<20,20,(1-ERF(R$10/SQRT(4*$F$4/($E$4*$C$4)*2*$D$4/$B$4)))*$L34) -> 90.975701 | S34: =IF((1-ERF(S$10/SQRT(4*$F$4/($E$4*$C$4)*2*$D$4/$B$4)))*$L34<20,20,(1-ERF(S$10/SQRT(4*$F$4/($E$4*$C$4)*2*$D$4/$B$4)))*$L34) -> 89.638975 | T34: =IF((1-ERF(T$10/SQRT(4*$F$4/($E$4*$C$4)*2*$D$4/$B$4)))*$L34<20,20,(1-ERF(T$10/SQRT(4*$F$4/($E$4*$C$4)*2*$D$4/$B$4)))*$L34) -> 88.304957 | ... BS34: =IF((1-ERF(BS$10/SQRT(4*$F$4/($E$4*$C$4)*2*$D$4/$B$4)))*$L34<20,20,(1-ERF(BS$10/SQRT(4*$F$4/($E$4*$C$4)*2*$D$4/$B$4)))*$L34) -> 20
B35: =B34+0.1 -> 0.099 | C35: =B35 -> 0.099 | E35: =($D$14*($B35+1))/2 -> 3.1840728 | F35: =($D$14*($B35-1))/2 -> -2.6104182 | H35: =(((C35+1)*EXP(E35))*(BESSELK(E35,0)+BESSELK(E35,1)))+(((1-C35)*EXP(F35))*(BESSELK(-F35,0)-BESSELK(-F35,1))) -> 1.6007465 | J35: =G35+H35+I35 -> 1.6007465 | K35: =J35/MAX($J$14:$J$57) -> 0.81725858 | L35: =IF($G$4>5,K35*$I$9,K35*$J$9)+20 -> 102.59538 | M35: =IF((1-ERF(M$10/SQRT(4*$F$4/($E$4*$C$4)*2*$D$4/$B$4)))*$L35<20,20,(1-ERF(M$10/SQRT(4*$F$4/($E$4*$C$4)*2*$D$4/$B$4)))*$L35) -> 101.2021 | N35: =IF((1-ERF(N$10/SQRT(4*$F$4/($E$4*$C$4)*2*$D$4/$B$4)))*$L35<20,20,(1-ERF(N$10/SQRT(4*$F$4/($E$4*$C$4)*2*$D$4/$B$4)))*$L35) -> 99.809217 | O35: =IF((1-ERF(O$10/SQRT(4*$F$4/($E$4*$C$4)*2*$D$4/$B$4)))*$L35<20,20,(1-ERF(O$10/SQRT(4*$F$4/($E$4*$C$4)*2*$D$4/$B$4)))*$L35) -> 98.417144 | P35: =IF((1-ERF(P$10/SQRT(4*$F$4/($E$4*$C$4)*2*$D$4/$B$4)))*$L35<20,20,(1-ERF(P$10/SQRT(4*$F$4/($E$4*$C$4)*2*$D$4/$B$4)))*$L35) -> 97.02628 | Q35: =IF((1-ERF(Q$10/SQRT(4*$F$4/($E$4*$C$4)*2*$D$4/$B$4)))*$L35<20,20,(1-ERF(Q$10/SQRT(4*$F$4/($E$4*$C$4)*2*$D$4/$B$4)))*$L35) -> 95.637027 | R35: =IF((1-ERF(R$10/SQRT(4*$F$4/($E$4*$C$4)*2*$D$4/$B$4)))*$L35<20,20,(1-ERF(R$10/SQRT(4*$F$4/($E$4*$C$4)*2*$D$4/$B$4)))*$L35) -> 94.249785 | S35: =IF((1-ERF(S$10/SQRT(4*$F$4/($E$4*$C$4)*2*$D$4/$B$4)))*$L35<20,20,(1-ERF(S$10/SQRT(4*$F$4/($E$4*$C$4)*2*$D$4/$B$4)))*$L35) -> 92.864952 | T35: =IF((1-ERF(T$10/SQRT(4*$F$4/($E$4*$C$4)*2*$D$4/$B$4)))*$L35<20,20,(1-ERF(T$10/SQRT(4*$F$4/($E$4*$C$4)*2*$D$4/$B$4)))*$L35) -> 91.482925 | ... BS35: =IF((1-ERF(BS$10/SQRT(4*$F$4/($E$4*$C$4)*2*$D$4/$B$4)))*$L35<20,20,(1-ERF(BS$10/SQRT(4*$F$4/($E$4*$C$4)*2*$D$4/$B$4)))*$L35) -> 20
B36: =B35+0.1 -> 0.199 | C36: =B36 -> 0.199 | E36: =($D$14*($B36+1))/2 -> 3.4737974 | F36: =($D$14*($B36-1))/2 -> -2.3206937 | H36: =(((C36+1)*EXP(E36))*(BESSELK(E36,0)+BESSELK(E36,1)))+(((1-C36)*EXP(F36))*(BESSELK(-F36,0)-BESSELK(-F36,1))) -> 1.6666519 | J36: =G36+H36+I36 -> 1.6666519 | K36: =J36/MAX($J$14:$J$57) -> 0.85090644 | L36: =IF($G$4>5,K36*$I$9,K36*$J$9)+20 -> 105.99597 | M36: =IF((1-ERF(M$10/SQRT(4*$F$4/($E$4*$C$4)*2*$D$4/$B$4)))*$L36<20,20,(1-ERF(M$10/SQRT(4*$F$4/($E$4*$C$4)*2*$D$4/$B$4)))*$L36) -> 104.5565 | N36: =IF((1-ERF(N$10/SQRT(4*$F$4/($E$4*$C$4)*2*$D$4/$B$4)))*$L36<20,20,(1-ERF(N$10/SQRT(4*$F$4/($E$4*$C$4)*2*$D$4/$B$4)))*$L36) -> 103.11745 | O36: =IF((1-ERF(O$10/SQRT(4*$F$4/($E$4*$C$4)*2*$D$4/$B$4)))*$L36<20,20,(1-ERF(O$10/SQRT(4*$F$4/($E$4*$C$4)*2*$D$4/$B$4)))*$L36) -> 101.67924 | P36: =IF((1-ERF(P$10/SQRT(4*$F$4/($E$4*$C$4)*2*$D$4/$B$4)))*$L36<20,20,(1-ERF(P$10/SQRT(4*$F$4/($E$4*$C$4)*2*$D$4/$B$4)))*$L36) -> 100.24227 | Q36: =IF((1-ERF(Q$10/SQRT(4*$F$4/($E$4*$C$4)*2*$D$4/$B$4)))*$L36<20,20,(1-ERF(Q$10/SQRT(4*$F$4/($E$4*$C$4)*2*$D$4/$B$4)))*$L36) -> 98.806974 | R36: =IF((1-ERF(R$10/SQRT(4*$F$4/($E$4*$C$4)*2*$D$4/$B$4)))*$L36<20,20,(1-ERF(R$10/SQRT(4*$F$4/($E$4*$C$4)*2*$D$4/$B$4)))*$L36) -> 97.373751 | S36: =IF((1-ERF(S$10/SQRT(4*$F$4/($E$4*$C$4)*2*$D$4/$B$4)))*$L36<20,20,(1-ERF(S$10/SQRT(4*$F$4/($E$4*$C$4)*2*$D$4/$B$4)))*$L36) -> 95.943017 | T36: =IF((1-ERF(T$10/SQRT(4*$F$4/($E$4*$C$4)*2*$D$4/$B$4)))*$L36<20,20,(1-ERF(T$10/SQRT(4*$F$4/($E$4*$C$4)*2*$D$4/$B$4)))*$L36) -> 94.515182 | ... BS36: =IF((1-ERF(BS$10/SQRT(4*$F$4/($E$4*$C$4)*2*$D$4/$B$4)))*$L36<20,20,(1-ERF(BS$10/SQRT(4*$F$4/($E$4*$C$4)*2*$D$4/$B$4)))*$L36) -> 20
... B44: =B43+0.1 -> 0.999 | C44: =B44 -> 0.999 | E44: =($D$14*($B44+1))/2 -> 5.7915938 | F44: =($D$14*($B44-1))/2 -> -0.0028972455 | H44: =(((C44+1)*EXP(E44))*(BESSELK(E44,0)+BESSELK(E44,1)))+(((1-C44)*EXP(F44))*(BESSELK(-F44,0)-BESSELK(-F44,1))) -> 1.7875219 | J44: =G44+H44+I44 -> 1.7875219 | K44: =J44/MAX($J$14:$J$57) -> 0.91261647 | L44: =IF($G$4>5,K44*$I$9,K44*$J$9)+20 -> 112.23263 | M44: =IF((1-ERF(M$10/SQRT(4*$F$4/($E$4*$C$4)*2*$D$4/$B$4)))*$L44<20,20,(1-ERF(M$10/SQRT(4*$F$4/($E$4*$C$4)*2*$D$4/$B$4)))*$L44) -> 110.70846 | N44: =IF((1-ERF(N$10/SQRT(4*$F$4/($E$4*$C$4)*2*$D$4/$B$4)))*$L44<20,20,(1-ERF(N$10/SQRT(4*$F$4/($E$4*$C$4)*2*$D$4/$B$4)))*$L44) -> 109.18475 | O44: =IF((1-ERF(O$10/SQRT(4*$F$4/($E$4*$C$4)*2*$D$4/$B$4)))*$L44<20,20,(1-ERF(O$10/SQRT(4*$F$4/($E$4*$C$4)*2*$D$4/$B$4)))*$L44) -> 107.66191 | P44: =IF((1-ERF(P$10/SQRT(4*$F$4/($E$4*$C$4)*2*$D$4/$B$4)))*$L44<20,20,(1-ERF(P$10/SQRT(4*$F$4/($E$4*$C$4)*2*$D$4/$B$4)))*$L44) -> 106.14039 | Q44: =IF((1-ERF(Q$10/SQRT(4*$F$4/($E$4*$C$4)*2*$D$4/$B$4)))*$L44<20,20,(1-ERF(Q$10/SQRT(4*$F$4/($E$4*$C$4)*2*$D$4/$B$4)))*$L44) -> 104.62064 | R44: =IF((1-ERF(R$10/SQRT(4*$F$4/($E$4*$C$4)*2*$D$4/$B$4)))*$L44<20,20,(1-ERF(R$10/SQRT(4*$F$4/($E$4*$C$4)*2*$D$4/$B$4)))*$L44) -> 103.10309 | S44: =IF((1-ERF(S$10/SQRT(4*$F$4/($E$4*$C$4)*2*$D$4/$B$4)))*$L44<20,20,(1-ERF(S$10/SQRT(4*$F$4/($E$4*$C$4)*2*$D$4/$B$4)))*$L44) -> 101.58817 | T44: =IF((1-ERF(T$10/SQRT(4*$F$4/($E$4*$C$4)*2*$D$4/$B$4)))*$L44<20,20,(1-ERF(T$10/SQRT(4*$F$4/($E$4*$C$4)*2*$D$4/$B$4)))*$L44) -> 100.07633 | ... BS44: =IF((1-ERF(BS$10/SQRT(4*$F$4/($E$4*$C$4)*2*$D$4/$B$4)))*$L44<20,20,(1-ERF(BS$10/SQRT(4*$F$4/($E$4*$C$4)*2*$D$4/$B$4)))*$L44) -> 20
B45: =B44+0.1 -> 1.099 | C45: =B45 -> 1.099 | E45: =($D$14*($B45+1))/2 -> 6.0813183 | F45: =($D$14*($B45-1))/2 -> 0.28682731 | I45: =(((C45+1)*EXP(E45))*(BESSELK(E45,0)+BESSELK(E45,1)))+(((1-C45)*EXP(F45))*(BESSELK(F45,0)+BESSELK(F45,1))) -> 1.5656878 | J45: =G45+H45+I45 -> 1.5656878 | K45: =J45/MAX($J$14:$J$57) -> 0.79935938 | L45: =IF($G$4>5,K45*$I$9,K45*$J$9)+20 -> 100.78642 | M45: =IF((1-ERF(M$10/SQRT(4*$F$4/($E$4*$C$4)*2*$D$4/$B$4)))*$L45<20,20,(1-ERF(M$10/SQRT(4*$F$4/($E$4*$C$4)*2*$D$4/$B$4)))*$L45) -> 99.4177 | N45: =IF((1-ERF(N$10/SQRT(4*$F$4/($E$4*$C$4)*2*$D$4/$B$4)))*$L45<20,20,(1-ERF(N$10/SQRT(4*$F$4/($E$4*$C$4)*2*$D$4/$B$4)))*$L45) -> 98.049379 | O45: =IF((1-ERF(O$10/SQRT(4*$F$4/($E$4*$C$4)*2*$D$4/$B$4)))*$L45<20,20,(1-ERF(O$10/SQRT(4*$F$4/($E$4*$C$4)*2*$D$4/$B$4)))*$L45) -> 96.681851 | P45: =IF((1-ERF(P$10/SQRT(4*$F$4/($E$4*$C$4)*2*$D$4/$B$4)))*$L45<20,20,(1-ERF(P$10/SQRT(4*$F$4/($E$4*$C$4)*2*$D$4/$B$4)))*$L45) -> 95.315511 | Q45: =IF((1-ERF(Q$10/SQRT(4*$F$4/($E$4*$C$4)*2*$D$4/$B$4)))*$L45<20,20,(1-ERF(Q$10/SQRT(4*$F$4/($E$4*$C$4)*2*$D$4/$B$4)))*$L45) -> 93.950753 | R45: =IF((1-ERF(R$10/SQRT(4*$F$4/($E$4*$C$4)*2*$D$4/$B$4)))*$L45<20,20,(1-ERF(R$10/SQRT(4*$F$4/($E$4*$C$4)*2*$D$4/$B$4)))*$L45) -> 92.587971 | S45: =IF((1-ERF(S$10/SQRT(4*$F$4/($E$4*$C$4)*2*$D$4/$B$4)))*$L45<20,20,(1-ERF(S$10/SQRT(4*$F$4/($E$4*$C$4)*2*$D$4/$B$4)))*$L45) -> 91.227556 | T45: =IF((1-ERF(T$10/SQRT(4*$F$4/($E$4*$C$4)*2*$D$4/$B$4)))*$L45<20,20,(1-ERF(T$10/SQRT(4*$F$4/($E$4*$C$4)*2*$D$4/$B$4)))*$L45) -> 89.869897 | ... BS45: =IF((1-ERF(BS$10/SQRT(4*$F$4/($E$4*$C$4)*2*$D$4/$B$4)))*$L45<20,20,(1-ERF(BS$10/SQRT(4*$F$4/($E$4*$C$4)*2*$D$4/$B$4)))*$L45) -> 20
B46: =B45+0.1 -> 1.199 | C46: =B46 -> 1.199 | E46: =($D$14*($B46+1))/2 -> 6.3710429 | F46: =($D$14*($B46-1))/2 -> 0.57655186 | I46: =(((C46+1)*EXP(E46))*(BESSELK(E46,0)+BESSELK(E46,1)))+(((1-C46)*EXP(F46))*(BESSELK(F46,0)+BESSELK(F46,1))) -> 1.4520153 | J46: =G46+H46+I46 -> 1.4520153 | K46: =J46/MAX($J$14:$J$57) -> 0.74132409 | L46: =IF($G$4>5,K46*$I$9,K46*$J$9)+20 -> 94.921142 | M46: =IF((1-ERF(M$10/SQRT(4*$F$4/($E$4*$C$4)*2*$D$4/$B$4)))*$L46<20,20,(1-ERF(M$10/SQRT(4*$F$4/($E$4*$C$4)*2*$D$4/$B$4)))*$L46) -> 93.632077 | N46: =IF((1-ERF(N$10/SQRT(4*$F$4/($E$4*$C$4)*2*$D$4/$B$4)))*$L46<20,20,(1-ERF(N$10/SQRT(4*$F$4/($E$4*$C$4)*2*$D$4/$B$4)))*$L46) -> 92.343386 | O46: =IF((1-ERF(O$10/SQRT(4*$F$4/($E$4*$C$4)*2*$D$4/$B$4)))*$L46<20,20,(1-ERF(O$10/SQRT(4*$F$4/($E$4*$C$4)*2*$D$4/$B$4)))*$L46) -> 91.055441 | P46: =IF((1-ERF(P$10/SQRT(4*$F$4/($E$4*$C$4)*2*$D$4/$B$4)))*$L46<20,20,(1-ERF(P$10/SQRT(4*$F$4/($E$4*$C$4)*2*$D$4/$B$4)))*$L46) -> 89.768615 | Q46: =IF((1-ERF(Q$10/SQRT(4*$F$4/($E$4*$C$4)*2*$D$4/$B$4)))*$L46<20,20,(1-ERF(Q$10/SQRT(4*$F$4/($E$4*$C$4)*2*$D$4/$B$4)))*$L46) -> 88.48328 | R46: =IF((1-ERF(R$10/SQRT(4*$F$4/($E$4*$C$4)*2*$D$4/$B$4)))*$L46<20,20,(1-ERF(R$10/SQRT(4*$F$4/($E$4*$C$4)*2*$D$4/$B$4)))*$L46) -> 87.199805 | S46: =IF((1-ERF(S$10/SQRT(4*$F$4/($E$4*$C$4)*2*$D$4/$B$4)))*$L46<20,20,(1-ERF(S$10/SQRT(4*$F$4/($E$4*$C$4)*2*$D$4/$B$4)))*$L46) -> 85.91856 | T46: =IF((1-ERF(T$10/SQRT(4*$F$4/($E$4*$C$4)*2*$D$4/$B$4)))*$L46<20,20,(1-ERF(T$10/SQRT(4*$F$4/($E$4*$C$4)*2*$D$4/$B$4)))*$L46) -> 84.63991 | ... BS46: =IF((1-ERF(BS$10/SQRT(4*$F$4/($E$4*$C$4)*2*$D$4/$B$4)))*$L46<20,20,(1-ERF(BS$10/SQRT(4*$F$4/($E$4*$C$4)*2*$D$4/$B$4)))*$L46) -> 20
B47: =B46+0.1 -> 1.299 | C47: =B47 -> 1.299 | E47: =($D$14*($B47+1))/2 -> 6.6607674 | F47: =($D$14*($B47-1))/2 -> 0.86627641 | I47: =(((C47+1)*EXP(E47))*(BESSELK(E47,0)+BESSELK(E47,1)))+(((1-C47)*EXP(F47))*(BESSELK(F47,0)+BESSELK(F47,1))) -> 1.3684 | J47: =G47+H47+I47 -> 1.3684 | K47: =J47/MAX($J$14:$J$57) -> 0.69863443 | L47: =IF($G$4>5,K47*$I$9,K47*$J$9)+20 -> 90.606755 | M47: =IF((1-ERF(M$10/SQRT(4*$F$4/($E$4*$C$4)*2*$D$4/$B$4)))*$L47<20,20,(1-ERF(M$10/SQRT(4*$F$4/($E$4*$C$4)*2*$D$4/$B$4)))*$L47) -> 89.376282 | N47: =IF((1-ERF(N$10/SQRT(4*$F$4/($E$4*$C$4)*2*$D$4/$B$4)))*$L47<20,20,(1-ERF(N$10/SQRT(4*$F$4/($E$4*$C$4)*2*$D$4/$B$4)))*$L47) -> 88.146164 | O47: =IF((1-ERF(O$10/SQRT(4*$F$4/($E$4*$C$4)*2*$D$4/$B$4)))*$L47<20,20,(1-ERF(O$10/SQRT(4*$F$4/($E$4*$C$4)*2*$D$4/$B$4)))*$L47) -> 86.91676 | P47: =IF((1-ERF(P$10/SQRT(4*$F$4/($E$4*$C$4)*2*$D$4/$B$4)))*$L47<20,20,(1-ERF(P$10/SQRT(4*$F$4/($E$4*$C$4)*2*$D$4/$B$4)))*$L47) -> 85.688423 | Q47: =IF((1-ERF(Q$10/SQRT(4*$F$4/($E$4*$C$4)*2*$D$4/$B$4)))*$L47<20,20,(1-ERF(Q$10/SQRT(4*$F$4/($E$4*$C$4)*2*$D$4/$B$4)))*$L47) -> 84.461509 | R47: =IF((1-ERF(R$10/SQRT(4*$F$4/($E$4*$C$4)*2*$D$4/$B$4)))*$L47<20,20,(1-ERF(R$10/SQRT(4*$F$4/($E$4*$C$4)*2*$D$4/$B$4)))*$L47) -> 83.236371 | S47: =IF((1-ERF(S$10/SQRT(4*$F$4/($E$4*$C$4)*2*$D$4/$B$4)))*$L47<20,20,(1-ERF(S$10/SQRT(4*$F$4/($E$4*$C$4)*2*$D$4/$B$4)))*$L47) -> 82.013361 | T47: =IF((1-ERF(T$10/SQRT(4*$F$4/($E$4*$C$4)*2*$D$4/$B$4)))*$L47<20,20,(1-ERF(T$10/SQRT(4*$F$4/($E$4*$C$4)*2*$D$4/$B$4)))*$L47) -> 80.792829 | ... BS47: =IF((1-ERF(BS$10/SQRT(4*$F$4/($E$4*$C$4)*2*$D$4/$B$4)))*$L47<20,20,(1-ERF(BS$10/SQRT(4*$F$4/($E$4*$C$4)*2*$D$4/$B$4)))*$L47) -> 20
...

Sheet 304SS
K1: 1
B2: FINDING PECLET NUMBER | C2: kg/m3 | D2: m | E2: J/kgK | F2: W/mK | K2: 1
B3: Cutting Speed, v | C3: Density, rho | D3: Half-width, b | E3: Specific Heat, c | F3: Thermal Conductivity, k | G3: Peclet Number, Pe | H3: Temperature, T | I3: Tool Width
B4: 0.3 | C4: 8030 | D4: =80*(10^-6) -> 8e-05 | E4: 500 | F4: 16.2 | G4: =(B4*C4*D4*E4)/(2*F4) -> 2.9740741 | H4: 20 | I4: =5*10^-3 -> 0.005
B5: =B4*60 -> 18
B6: =B5*3.2 -> 57.6
B7: FINDING FLASH TEMPERATURE
B8: Cutting Force, F | C8: Density, rho | D8: Half-width, b | E8: Specific Heat, c | F8: Thermal Conductivity, k | G8: Peclet Number, Pe | H8: C4 | I8: Flash Temp (Pe>5) | J8: Flash Temp (Pe<5)
B9: 70 | C9: =C4 -> 8030 | D9: =D4 -> 8e-05 | E9: =E4 -> 500 | F9: =F4 -> 16.2 | G9: =G4 -> 2.9740741 | H9: =(0.00527*(G4^3))-(0.192*(G4^2))+2.39*G4 -> 5.5484074 | I9: =(0.399)*((2*B9*B4)/(F9*I4))*(SQRT((F9)/(C9*E9*B4*D9))) -> 84.829377 | J9: =(0.159*H9)*((2*B9)/(C9*E9*D9*I4)) -> 76.903829
L10: z [m] | M10: =M11*$D$4 -> 8e-07 | N10: =N11*$D$4 -> 1.6e-06 | O10: =O11*$D$4 -> 2.4e-06 | P10: =P11*$D$4 -> 3.2e-06 | Q10: =Q11*$D$4 -> 4e-06 | R10: =R11*$D$4 -> 4.8e-06 | S10: =S11*$D$4 -> 5.6e-06 | T10: =T11*$D$4 -> 6.4e-06 | ... BS10: =BS11*$D$4 -> 0.0004
K11: z/b | L11: 0 | M11: 0.01 | N11: 0.02 | O11: 0.03 | P11: 0.04 | Q11: 0.05 | R11: 0.06 | S11: 0.07 | T11: 0.08 | U11: 0.09 | V11: 0.1 | W11: 0.11 | X11: 0.12 | Y11: 0.13 | Z11: 0.14 | AA11: 0.15 | AB11: 0.16 | AC11: 0.17 | AD11: 0.18 | AE11: 0.19 | AF11: 0.2 | AG11: 0.21 | AH11: 0.22 | AI11: 0.23 | AJ11: 0.24 | AK11: 0.25 | AL11: 0.26 | AM11: 0.27 | AN11: 0.28 | AO11: 0.29 | AP11: 0.3 | AQ11: 0.31 | AR11: 0.32 | AS11: 0.33 | AT11: 0.34 | AU11: 0.35 | AV11: 0.36 | AW11: 0.37 | AX11: 0.38 | AY11: 0.39 | AZ11: 0.4 | BA11: 0.41 | BB11: 0.42 | BC11: 0.43 | BD11: 0.44 | BE11: 0.45 | BF11: 0.46 | BG11: 0.47 | BH11: 0.48 | BI11: 0.49 | BJ11: 0.5 | BK11: 1 | BL11: 1.5 | BM11: 2 | BN11: 2.5 | BO11: 3 | BP11: 3.5 | BQ11: 4 | BR11: 4.5 | BS11: 5
B12: STEADY STATE TEMPERATURE
B13: x/b | D13: Peclet Number, Pe | E13: P+ | F13: P- | G13: Steady State Temp (x/b<-1) | H13: Steady State Temp (-1<x/b<1) | I13: Steady State Temp (1,x/b) | J13: summed temp profile | K13: normalized | L13: f(T)
B14: -2.001 | C14: =B14 -> -2.001 | D14: =G4 -> 2.9740741 | E14: =($D$14*($B14+1))/2 -> -1.4885241 | F14: =($D$14*($B14-1))/2 -> -4.4625981 | G14: =((C14+1)*(EXP(E14))*(BESSELK(-E14,0)-BESSELK(-E14,1)))+((1-C14)*EXP(F14)*(BESSELK(-F14,0)-BESSELK(-F14,1))) -> 0.01465919 | J14: =G14+H14+I14 -> 0.01465919 | K14: =J14/MAX($J$14:$J$57) -> 0.005566999 | L14: =IF($G$4>5,K14*$I$9,K14*$J$9)+20 -> 20.428124 | M14: =IF((1-ERF(M$10/SQRT(4*$F$4/($E$4*$C$4)*2*$D$4/$B$4)))*$L14<20,20,(1-ERF(M$10/SQRT(4*$F$4/($E$4*$C$4)*2*$D$4/$B$4)))*$L14) -> 20.229368 | N14: =IF((1-ERF(N$10/SQRT(4*$F$4/($E$4*$C$4)*2*$D$4/$B$4)))*$L14<20,20,(1-ERF(N$10/SQRT(4*$F$4/($E$4*$C$4)*2*$D$4/$B$4)))*$L14) -> 20.030643 | O14: =IF((1-ERF(O$10/SQRT(4*$F$4/($E$4*$C$4)*2*$D$4/$B$4)))*$L14<20,20,(1-ERF(O$10/SQRT(4*$F$4/($E$4*$C$4)*2*$D$4/$B$4)))*$L14) -> 20 | P14: =IF((1-ERF(P$10/SQRT(4*$F$4/($E$4*$C$4)*2*$D$4/$B$4)))*$L14<20,20,(1-ERF(P$10/SQRT(4*$F$4/($E$4*$C$4)*2*$D$4/$B$4)))*$L14) -> 20 | Q14: =IF((1-ERF(Q$10/SQRT(4*$F$4/($E$4*$C$4)*2*$D$4/$B$4)))*$L14<20,20,(1-ERF(Q$10/SQRT(4*$F$4/($E$4*$C$4)*2*$D$4/$B$4)))*$L14) -> 20 | R14: =IF((1-ERF(R$10/SQRT(4*$F$4/($E$4*$C$4)*2*$D$4/$B$4)))*$L14<20,20,(1-ERF(R$10/SQRT(4*$F$4/($E$4*$C$4)*2*$D$4/$B$4)))*$L14) -> 20 | S14: =IF((1-ERF(S$10/SQRT(4*$F$4/($E$4*$C$4)*2*$D$4/$B$4)))*$L14<20,20,(1-ERF(S$10/SQRT(4*$F$4/($E$4*$C$4)*2*$D$4/$B$4)))*$L14) -> 20 | T14: =IF((1-ERF(T$10/SQRT(4*$F$4/($E$4*$C$4)*2*$D$4/$B$4)))*$L14<20,20,(1-ERF(T$10/SQRT(4*$F$4/($E$4*$C$4)*2*$D$4/$B$4)))*$L14) -> 20 | ... BS14: =IF((1-ERF(BS$10/SQRT(4*$F$4/($E$4*$C$4)*2*$D$4/$B$4)))*$L14<20,20,(1-ERF(BS$10/SQRT(4*$F$4/($E$4*$C$4)*2*$D$4/$B$4)))*$L14) -> 20
B15: =B14+0.1 -> -1.901 | C15: =B15 -> -1.901 | E15: =($D$14*($B15+1))/2 -> -1.3398204 | F15: =($D$14*($B15-1))/2 -> -4.3138944 | G15: =((C15+1)*(EXP(E15))*(BESSELK(-E15,0)-BESSELK(-E15,1)))+((1-C15)*EXP(F15)*(BESSELK(-F15,0)-BESSELK(-F15,1))) -> 0.020494486 | J15: =G15+H15+I15 -> 0.020494486 | K15: =J15/MAX($J$14:$J$57) -> 0.007783021 | L15: =IF($G$4>5,K15*$I$9,K15*$J$9)+20 -> 20.598544 | M15: =IF((1-ERF(M$10/SQRT(4*$F$4/($E$4*$C$4)*2*$D$4/$B$4)))*$L15<20,20,(1-ERF(M$10/SQRT(4*$F$4/($E$4*$C$4)*2*$D$4/$B$4)))*$L15) -> 20.398131 | N15: =IF((1-ERF(N$10/SQRT(4*$F$4/($E$4*$C$4)*2*$D$4/$B$4)))*$L15<20,20,(1-ERF(N$10/SQRT(4*$F$4/($E$4*$C$4)*2*$D$4/$B$4)))*$L15) -> 20.197747 | O15: =IF((1-ERF(O$10/SQRT(4*$F$4/($E$4*$C$4)*2*$D$4/$B$4)))*$L15<20,20,(1-ERF(O$10/SQRT(4*$F$4/($E$4*$C$4)*2*$D$4/$B$4)))*$L15) -> 20 | P15: =IF((1-ERF(P$10/SQRT(4*$F$4/($E$4*$C$4)*2*$D$4/$B$4)))*$L15<20,20,(1-ERF(P$10/SQRT(4*$F$4/($E$4*$C$4)*2*$D$4/$B$4)))*$L15) -> 20 | Q15: =IF((1-ERF(Q$10/SQRT(4*$F$4/($E$4*$C$4)*2*$D$4/$B$4)))*$L15<20,20,(1-ERF(Q$10/SQRT(4*$F$4/($E$4*$C$4)*2*$D$4/$B$4)))*$L15) -> 20 | R15: =IF((1-ERF(R$10/SQRT(4*$F$4/($E$4*$C$4)*2*$D$4/$B$4)))*$L15<20,20,(1-ERF(R$10/SQRT(4*$F$4/($E$4*$C$4)*2*$D$4/$B$4)))*$L15) -> 20 | S15: =IF((1-ERF(S$10/SQRT(4*$F$4/($E$4*$C$4)*2*$D$4/$B$4)))*$L15<20,20,(1-ERF(S$10/SQRT(4*$F$4/($E$4*$C$4)*2*$D$4/$B$4)))*$L15) -> 20 | T15: =IF((1-ERF(T$10/SQRT(4*$F$4/($E$4*$C$4)*2*$D$4/$B$4)))*$L15<20,20,(1-ERF(T$10/SQRT(4*$F$4/($E$4*$C$4)*2*$D$4/$B$4)))*$L15) -> 20 | ... BS15: =IF((1-ERF(BS$10/SQRT(4*$F$4/($E$4*$C$4)*2*$D$4/$B$4)))*$L15<20,20,(1-ERF(BS$10/SQRT(4*$F$4/($E$4*$C$4)*2*$D$4/$B$4)))*$L15) -> 20
B16: =B15+0.1 -> -1.801 | C16: =B16 -> -1.801 | E16: =($D$14*($B16+1))/2 -> -1.1911167 | F16: =($D$14*($B16-1))/2 -> -4.1651907 | G16: =((C16+1)*(EXP(E16))*(BESSELK(-E16,0)-BESSELK(-E16,1)))+((1-C16)*EXP(F16)*(BESSELK(-F16,0)-BESSELK(-F16,1))) -> 0.028748029 | J16: =G16+H16+I16 -> 0.028748029 | K16: =J16/MAX($J$14:$J$57) -> 0.010917401 | L16: =IF($G$4>5,K16*$I$9,K16*$J$9)+20 -> 20.83959 | M16: =IF((1-ERF(M$10/SQRT(4*$F$4/($E$4*$C$4)*2*$D$4/$B$4)))*$L16<20,20,(1-ERF(M$10/SQRT(4*$F$4/($E$4*$C$4)*2*$D$4/$B$4)))*$L16) -> 20.636831 | N16: =IF((1-ERF(N$10/SQRT(4*$F$4/($E$4*$C$4)*2*$D$4/$B$4)))*$L16<20,20,(1-ERF(N$10/SQRT(4*$F$4/($E$4*$C$4)*2*$D$4/$B$4)))*$L16) -> 20.434103 | O16: =IF((1-ERF(O$10/SQRT(4*$F$4/($E$4*$C$4)*2*$D$4/$B$4)))*$L16<20,20,(1-ERF(O$10/SQRT(4*$F$4/($E$4*$C$4)*2*$D$4/$B$4)))*$L16) -> 20.231435 | P16: =IF((1-ERF(P$10/SQRT(4*$F$4/($E$4*$C$4)*2*$D$4/$B$4)))*$L16<20,20,(1-ERF(P$10/SQRT(4*$F$4/($E$4*$C$4)*2*$D$4/$B$4)))*$L16) -> 20.028857 | Q16: =IF((1-ERF(Q$10/SQRT(4*$F$4/($E$4*$C$4)*2*$D$4/$B$4)))*$L16<20,20,(1-ERF(Q$10/SQRT(4*$F$4/($E$4*$C$4)*2*$D$4/$B$4)))*$L16) -> 20 | R16: =IF((1-ERF(R$10/SQRT(4*$F$4/($E$4*$C$4)*2*$D$4/$B$4)))*$L16<20,20,(1-ERF(R$10/SQRT(4*$F$4/($E$4*$C$4)*2*$D$4/$B$4)))*$L16) -> 20 | S16: =IF((1-ERF(S$10/SQRT(4*$F$4/($E$4*$C$4)*2*$D$4/$B$4)))*$L16<20,20,(1-ERF(S$10/SQRT(4*$F$4/($E$4*$C$4)*2*$D$4/$B$4)))*$L16) -> 20 | T16: =IF((1-ERF(T$10/SQRT(4*$F$4/($E$4*$C$4)*2*$D$4/$B$4)))*$L16<20,20,(1-ERF(T$10/SQRT(4*$F$4/($E$4*$C$4)*2*$D$4/$B$4)))*$L16) -> 20 | ... BS16: =IF((1-ERF(BS$10/SQRT(4*$F$4/($E$4*$C$4)*2*$D$4/$B$4)))*$L16<20,20,(1-ERF(BS$10/SQRT(4*$F$4/($E$4*$C$4)*2*$D$4/$B$4)))*$L16) -> 20
B17: =B16+0.1 -> -1.701 | C17: =B17 -> -1.701 | E17: =($D$14*($B17+1))/2 -> -1.042413 | F17: =($D$14*($B17-1))/2 -> -4.016487 | G17: =((C17+1)*(EXP(E17))*(BESSELK(-E17,0)-BESSELK(-E17,1)))+((1-C17)*EXP(F17)*(BESSELK(-F17,0)-BESSELK(-F17,1))) -> 0.040487662 | J17: =G17+H17+I17 -> 0.040487662 | K17: =J17/MAX($J$14:$J$57) -> 0.015375664 | L17: =IF($G$4>5,K17*$I$9,K17*$J$9)+20 -> 21.182447 | M17: =IF((1-ERF(M$10/SQRT(4*$F$4/($E$4*$C$4)*2*$D$4/$B$4)))*$L17<20,20,(1-ERF(M$10/SQRT(4*$F$4/($E$4*$C$4)*2*$D$4/$B$4)))*$L17) -> 20.976353 | N17: =IF((1-ERF(N$10/SQRT(4*$F$4/($E$4*$C$4)*2*$D$4/$B$4)))*$L17<20,20,(1-ERF(N$10/SQRT(4*$F$4/($E$4*$C$4)*2*$D$4/$B$4)))*$L17) -> 20.770289 | O17: =IF((1-ERF(O$10/SQRT(4*$F$4/($E$4*$C$4)*2*$D$4/$B$4)))*$L17<20,20,(1-ERF(O$10/SQRT(4*$F$4/($E$4*$C$4)*2*$D$4/$B$4)))*$L17) -> 20.564287 | P17: =IF((1-ERF(P$10/SQRT(4*$F$4/($E$4*$C$4)*2*$D$4/$B$4)))*$L17<20,20,(1-ERF(P$10/SQRT(4*$F$4/($E$4*$C$4)*2*$D$4/$B$4)))*$L17) -> 20.358376 | Q17: =IF((1-ERF(Q$10/SQRT(4*$F$4/($E$4*$C$4)*2*$D$4/$B$4)))*$L17<20,20,(1-ERF(Q$10/SQRT(4*$F$4/($E$4*$C$4)*2*$D$4/$B$4)))*$L17) -> 20.152588 | R17: =IF((1-ERF(R$10/SQRT(4*$F$4/($E$4*$C$4)*2*$D$4/$B$4)))*$L17<20,20,(1-ERF(R$10/SQRT(4*$F$4/($E$4*$C$4)*2*$D$4/$B$4)))*$L17) -> 20 | S17: =IF((1-ERF(S$10/SQRT(4*$F$4/($E$4*$C$4)*2*$D$4/$B$4)))*$L17<20,20,(1-ERF(S$10/SQRT(4*$F$4/($E$4*$C$4)*2*$D$4/$B$4)))*$L17) -> 20 | T17: =IF((1-ERF(T$10/SQRT(4*$F$4/($E$4*$C$4)*2*$D$4/$B$4)))*$L17<20,20,(1-ERF(T$10/SQRT(4*$F$4/($E$4*$C$4)*2*$D$4/$B$4)))*$L17) -> 20 | ... BS17: =IF((1-ERF(BS$10/SQRT(4*$F$4/($E$4*$C$4)*2*$D$4/$B$4)))*$L17<20,20,(1-ERF(BS$10/SQRT(4*$F$4/($E$4*$C$4)*2*$D$4/$B$4)))*$L17) -> 20
B18: =B17+0.1 -> -1.601 | C18: =B18 -> -1.601 | E18: =($D$14*($B18+1))/2 -> -0.89370926 | F18: =($D$14*($B18-1))/2 -> -3.8677833 | G18: =((C18+1)*(EXP(E18))*(BESSELK(-E18,0)-BESSELK(-E18,1)))+((1-C18)*EXP(F18)*(BESSELK(-F18,0)-BESSELK(-F18,1))) -> 0.057304809 | J18: =G18+H18+I18 -> 0.057304809 | K18: =J18/MAX($J$14:$J$57) -> 0.021762172 | L18: =IF($G$4>5,K18*$I$9,K18*$J$9)+20 -> 21.673594 | M18: =IF((1-ERF(M$10/SQRT(4*$F$4/($E$4*$C$4)*2*$D$4/$B$4)))*$L18<20,20,(1-ERF(M$10/SQRT(4*$F$4/($E$4*$C$4)*2*$D$4/$B$4)))*$L18) -> 21.462721 | N18: =IF((1-ERF(N$10/SQRT(4*$F$4/($E$4*$C$4)*2*$D$4/$B$4)))*$L18<20,20,(1-ERF(N$10/SQRT(4*$F$4/($E$4*$C$4)*2*$D$4/$B$4)))*$L18) -> 21.25188 | O18: =IF((1-ERF(O$10/SQRT(4*$F$4/($E$4*$C$4)*2*$D$4/$B$4)))*$L18<20,20,(1-ERF(O$10/SQRT(4*$F$4/($E$4*$C$4)*2*$D$4/$B$4)))*$L18) -> 21.041101 | P18: =IF((1-ERF(P$10/SQRT(4*$F$4/($E$4*$C$4)*2*$D$4/$B$4)))*$L18<20,20,(1-ERF(P$10/SQRT(4*$F$4/($E$4*$C$4)*2*$D$4/$B$4)))*$L18) -> 20.830416 | Q18: =IF((1-ERF(Q$10/SQRT(4*$F$4/($E$4*$C$4)*2*$D$4/$B$4)))*$L18<20,20,(1-ERF(Q$10/SQRT(4*$F$4/($E$4*$C$4)*2*$D$4/$B$4)))*$L18) -> 20.619856 | R18: =IF((1-ERF(R$10/SQRT(4*$F$4/($E$4*$C$4)*2*$D$4/$B$4)))*$L18<20,20,(1-ERF(R$10/SQRT(4*$F$4/($E$4*$C$4)*2*$D$4/$B$4)))*$L18) -> 20.409453 | S18: =IF((1-ERF(S$10/SQRT(4*$F$4/($E$4*$C$4)*2*$D$4/$B$4)))*$L18<20,20,(1-ERF(S$10/SQRT(4*$F$4/($E$4*$C$4)*2*$D$4/$B$4)))*$L18) -> 20.199237 | T18: =IF((1-ERF(T$10/SQRT(4*$F$4/($E$4*$C$4)*2*$D$4/$B$4)))*$L18<20,20,(1-ERF(T$10/SQRT(4*$F$4/($E$4*$C$4)*2*$D$4/$B$4)))*$L18) -> 20 | ... BS18: =IF((1-ERF(BS$10/SQRT(4*$F$4/($E$4*$C$4)*2*$D$4/$B$4)))*$L18<20,20,(1-ERF(BS$10/SQRT(4*$F$4/($E$4*$C$4)*2*$D$4/$B$4)))*$L18) -> 20
B19: =B18+0.1 -> -1.501 | C19: =B19 -> -1.501 | E19: =($D$14*($B19+1))/2 -> -0.74500556 | F19: =($D$14*($B19-1))/2 -> -3.7190796 | G19: =((C19+1)*(EXP(E19))*(BESSELK(-E19,0)-BESSELK(-E19,1)))+((1-C19)*EXP(F19)*(BESSELK(-F19,0)-BESSELK(-F19,1))) -> 0.081620533 | J19: =G19+H19+I19 -> 0.081620533 | K19: =J19/MAX($J$14:$J$57) -> 0.030996353 | L19: =IF($G$4>5,K19*$I$9,K19*$J$9)+20 -> 22.383738 | M19: =IF((1-ERF(M$10/SQRT(4*$F$4/($E$4*$C$4)*2*$D$4/$B$4)))*$L19<20,20,(1-ERF(M$10/SQRT(4*$F$4/($E$4*$C$4)*2*$D$4/$B$4)))*$L19) -> 22.165956 | N19: =IF((1-ERF(N$10/SQRT(4*$F$4/($E$4*$C$4)*2*$D$4/$B$4)))*$L19<20,20,(1-ERF(N$10/SQRT(4*$F$4/($E$4*$C$4)*2*$D$4/$B$4)))*$L19) -> 21.948206 | O19: =IF((1-ERF(O$10/SQRT(4*$F$4/($E$4*$C$4)*2*$D$4/$B$4)))*$L19<20,20,(1-ERF(O$10/SQRT(4*$F$4/($E$4*$C$4)*2*$D$4/$B$4)))*$L19) -> 21.730521 | P19: =IF((1-ERF(P$10/SQRT(4*$F$4/($E$4*$C$4)*2*$D$4/$B$4)))*$L19<20,20,(1-ERF(P$10/SQRT(4*$F$4/($E$4*$C$4)*2*$D$4/$B$4)))*$L19) -> 21.512932 | Q19: =IF((1-ERF(Q$10/SQRT(4*$F$4/($E$4*$C$4)*2*$D$4/$B$4)))*$L19<20,20,(1-ERF(Q$10/SQRT(4*$F$4/($E$4*$C$4)*2*$D$4/$B$4)))*$L19) -> 21.295474 | R19: =IF((1-ERF(R$10/SQRT(4*$F$4/($E$4*$C$4)*2*$D$4/$B$4)))*$L19<20,20,(1-ERF(R$10/SQRT(4*$F$4/($E$4*$C$4)*2*$D$4/$B$4)))*$L19) -> 21.078176 | S19: =IF((1-ERF(S$10/SQRT(4*$F$4/($E$4*$C$4)*2*$D$4/$B$4)))*$L19<20,20,(1-ERF(S$10/SQRT(4*$F$4/($E$4*$C$4)*2*$D$4/$B$4)))*$L19) -> 20.861073 | T19: =IF((1-ERF(T$10/SQRT(4*$F$4/($E$4*$C$4)*2*$D$4/$B$4)))*$L19<20,20,(1-ERF(T$10/SQRT(4*$F$4/($E$4*$C$4)*2*$D$4/$B$4)))*$L19) -> 20.644195 | ... BS19: =IF((1-ERF(BS$10/SQRT(4*$F$4/($E$4*$C$4)*2*$D$4/$B$4)))*$L19<20,20,(1-ERF(BS$10/SQRT(4*$F$4/($E$4*$C$4)*2*$D$4/$B$4)))*$L19) -> 20
